<mujoco model='humanoid'>
  <compiler inertiafromgeom='true' angle='degree' />
  <custom>
    <numeric name="frame_skip" data="4" />
  </custom>
  <default>
    <joint limited='true' damping='1' armature='1' />
    <geom contype='1' conaffinity='1' condim='1' rgba='0.8 0.6 .4 1' margin="0.001" solref=".02 1" solimp=".8 .8 .01" material="geom" />
    <position ctrlrange='-.4 .4' ctrllimited='true' kp='5'/>
  </default>
  <option integrator="RK4" iterations="50" solver="PGS" timestep="0.003">
      <!-- <flags solverstat="enable" energy="enable"/>-->
  </option>
  <size nuser_geom='1' nkey='5' />
  <visual>
    <map fogstart="3" fogend="5" />
  </visual>
  <asset>
    <texture type="skybox" builtin="gradient" width="100" height="100" rgb1="1 1 1" rgb2="0 0 0" />
    <texture name="texgeom" type="cube" builtin="flat" mark="cross" width="127" height="1278" rgb1="0.8 0.6 0.4" rgb2="0.8 0.6 0.4" markrgb="1 1 1" random="0.01" />
    <texture name="texplane" type="2d" builtin="checker" rgb1="0 0 0" rgb2="0.8 0.8 0.8" width="100" height="100" />
    <material name='MatPlane' texture="texplane" shininess="1" texrepeat="60 60" specular="1"  reflectance="0.5" />
    <material name='geom' texture="texgeom" texuniform="true" />
  </asset>
  <worldbody>
    <light cutoff="100" diffuse="1 1 1" dir="-0 0 -1.3" directional="true" exponent="1" pos="0 0 1.3" specular=".1 .1 .1"/>
    <geom condim="3" friction="1 .1 .1" material="MatPlane" name="floor" pos="0 0 0" rgba="0.8 0.9 0.8 1" size="20 20 0.125" type="plane"/>
    <body name='torso' pos='0 0 1.4'>
      <camera name="track" mode="trackcom" pos="0 -4 0" xyaxes="1 0 0 0 0 1"/>
      <joint name='root' type='free' pos='0 0 0' limited='false' damping='0' armature='0' stiffness='0' />
      <geom name='torso1' type='capsule' fromto='0 -.09 0 0 .09 0' size='0.07' />
      <geom name='head' type='sphere' pos='0 0 .19' size='.09' user='258' />
      <geom name='uwaist' type='capsule' fromto='-.01 -.06 -.12 -.01 .06 -.12' size='0.06' />
      <body name='lwaist' pos='-.01 0 -0.260' quat='1.000 0 -0.002 0'>
        <geom name='lwaist' type='capsule' fromto='0 -.06 0 0 .06 0' size='0.06' />
        <joint name='abdomen_z' type='hinge' pos='0 0 0.065' axis='0 0 1' range='-45 45' damping='5' stiffness='20' armature='0.02' />
        <joint name='abdomen_y' type='hinge' pos='0 0 0.065' axis='0 1 0' range='-75 30' damping='5' stiffness='10' armature='0.02' />
        <body name='pelvis' pos='0 0 -0.165' quat='1.000 0 -0.002 0'>
          <joint name='abdomen_x' type='hinge' pos='0 0 0.1' axis='1 0 0' range='-35 35' damping='5' stiffness='10' armature='0.02' />
          <geom name='butt' type='capsule' fromto='-.02 -.07 0 -.02 .07 0' size='0.09' />
          <body name='right_thigh' pos='0 -0.1 -0.04'>
            <joint name='right_hip_x' type='hinge' pos='0 0 0' axis='1 0 0' range='-25 5' damping='5' stiffness='10' armature='0.01' />
            <joint name='right_hip_z' type='hinge' pos='0 0 0' axis='0 0 1' range='-60 35' damping='5' stiffness='10' armature='0.01' />
            <joint name='right_hip_y' type='hinge' pos='0 0 0' axis='0 1 0' range='-110 20' damping='5' stiffness='20' armature='0.0080' />
            <geom name='right_thigh1' type='capsule' fromto='0 0 0 0 0.01 -.34' size='0.06' />
            <body name='right_shin' pos='0 0.01 -0.403'>
              <joint name='right_knee' type='hinge' pos='0 0 .02' axis='0 -1 0' range='-160 -2' armature='0.0060' />
              <geom name='right_shin1' type='capsule' fromto='0 0 0 0 0 -.3' size='0.049' />
              <body name='right_foot' pos='0 0 -.39'>
                <joint name='right_ankle_y' type='hinge' pos='0 0 0.08' axis='0 1 0' range='-50 50' stiffness='4' armature='0.0008' />
                <joint name='right_ankle_x' type='hinge' pos='0 0 0.04' axis='1 0 0.5' range='-50 50' stiffness='1' armature='0.0006' />
                <geom name='right_foot_cap1' type='capsule' fromto='-.07 -0.02 0 0.14 -0.04 0' size='0.027' />
                <geom name='right_foot_cap2' type='capsule' fromto='-.07 0 0 0.14 0.02 0' size='0.027' />
              </body>
            </body>
          </body>
          <body name='left_thigh' pos='0 0.1 -0.04'>
            <joint name='left_hip_x' type='hinge' pos='0 0 0' axis='-1 0 0' range='-25 5' damping='5' stiffness='10' armature='0.01' />
            <joint name='left_hip_z' type='hinge' pos='0 0 0' axis='0 0 -1' range='-60 35' damping='5' stiffness='10' armature='0.01' />
            <joint name='left_hip_y' type='hinge' pos='0 0 0' axis='0 1 0' range='-120 20' damping='5' stiffness='20' armature='0.01' />
            <geom name='left_thigh1' type='capsule' fromto='0 0 0 0 -0.01 -.34' size='0.06' />
            <body name='left_shin' pos='0 -0.01 -0.403'>
              <joint name='left_knee' type='hinge' pos='0 0 .02' axis='0 -1 0' range='-160 -2' stiffness='1' armature='0.0060' />
              <geom name='left_shin1' type='capsule' fromto='0 0 0 0 0 -.3' size='0.049' />
              <body name='left_foot' pos='0 0 -.39'>
                <joint name='left_ankle_y' type='hinge' pos='0 0 0.08' axis='0 1 0' range='-50 50' stiffness='4' armature='0.0008' />
                <joint name='left_ankle_x' type='hinge' pos='0 0 0.04' axis='1 0 0.5' range='-50 50' stiffness='1' armature='0.0006' />
                <geom name='left_foot_cap1' type='capsule' fromto='-.07 0.02 0 0.14 0.04 0' size='0.027' />
                <geom name='left_foot_cap2' type='capsule' fromto='-.07 0 0 0.14 -0.02 0' size='0.027' />
              </body>
            </body>
          </body>
        </body>
      </body>
      <body name='right_upper_arm' pos='0 -0.2 0.06'>
        <joint name='right_shoulder1' type='hinge' pos='0 0 0' axis='1 0 0' range='-85 60' stiffness='1' armature='0.0068' />
        <joint name='right_shoulder2' type='hinge' pos='0 0 0' axis='0 1 0' range='-85 60' stiffness='1' armature='0.0051' />
        <geom name='right_uarm1' type='capsule' fromto='0 0 0 0 0 -.24' size='0.04' />
        <body name='right_lower_arm' pos='0 0 -.24'>
          <joint name='right_elbow' type='hinge' pos='0 0 0' axis='0 0 -1' range='-50 90' stiffness='0' armature='0.0028' />
          <geom name='right_larm' type='capsule' fromto='0 0 0 0 0 -.31' size='0.031' />
          <geom name='right_hand' type='sphere' pos='0 0 -.31' size='0.04' />
          <camera pos="0 0 0" />
        </body>
      </body>
      <body name='left_upper_arm' pos='0 0.2 0.06'>
        <joint name='left_shoulder1' type='hinge' pos='0 0 0' axis='1 0 0' range='-60 85' stiffness='1' armature='0.0068' />
        <joint name='left_shoulder2' type='hinge' pos='0 0 0' axis='0 1 0' range='-60 85' stiffness='1' armature='0.0051' />
        <geom name='left_uarm1' type='capsule' fromto='0 0 0 0 0 -.24' size='0.04' />
        <body name='left_lower_arm' pos='0 0 -.24'>
          <joint name='left_elbow' type='hinge' pos='0 0 0' axis='0 0 -1' range='-50 90' stiffness='0' armature='0.0028' />
          <geom name='left_larm' type='capsule' fromto='0 0 0 0 0 -.31' size='0.031' />
          <geom name='left_hand' type='sphere' pos='0 0 -.31' size='0.04' />
        </body>
      </body>
    </body>
  </worldbody>
  <tendon>
    <fixed name='left_hipknee'>
      <joint joint='left_hip_y' coef='-1' />
      <joint joint='left_knee' coef='1' />
    </fixed>
    <fixed name='right_hipknee'>
      <joint joint='right_hip_y' coef='-1' />
      <joint joint='right_knee' coef='1' />
    </fixed>
  </tendon>
  
  <actuator>
    <position name='abdomen_z' gear='5' joint='abdomen_z' />
    <position name='abdomen_y' gear='5' joint='abdomen_y' />
    <position name='abdomen_x' gear='5' joint='abdomen_x' />
    <position name='right_hip_x' gear='5' joint='right_hip_x' />
    <position name='right_hip_z' gear='5' joint='right_hip_z' />
    <position name='right_hip_y' gear='5' joint='right_hip_y' />
    <position name='right_knee' gear='5' joint='right_knee' />
    <position name='right_ankle_y' gear='5' joint='right_ankle_y' />
    <position name='right_ankle_x' gear='5' joint='right_ankle_x' />
    <position name='left_hip_x' gear='5' joint='left_hip_x' />
    <position name='left_hip_z' gear='5' joint='left_hip_z' />
    <position name='left_hip_y' gear='5' joint='left_hip_y' />
    <position name='left_knee' gear='5' joint='left_knee' />
    <position name='left_ankle_y' gear='5' joint='left_ankle_y' />
    <position name='left_ankle_x' gear='5' joint='left_ankle_x' />
    <position name='right_shoulder1' gear='5' joint='right_shoulder1' />
    <position name='right_shoulder2' gear='5' joint='right_shoulder2' />
    <position name='right_elbow' gear='5' joint='right_elbow' />
    <position name='left_shoulder1' gear='5' joint='left_shoulder1' />
    <position name='left_shoulder2' gear='5' joint='left_shoulder2' />
    <position name='left_elbow' gear='5' joint='left_elbow' />
  </actuator>
</mujoco>
