<?xml version="1.0"?>
<robot xmlns:xacro="http://ros.org/wiki/xacro" name="tobe">

	<!-- Import mass property (inertia) -->
	<xacro:include filename="$(find tobe_description)/inertia/Torso.xacro"/>
	<xacro:include filename="$(find tobe_description)/inertia/F1.xacro"/>
	<xacro:include filename="$(find tobe_description)/inertia/F5.xacro"/>
	<xacro:include filename="$(find tobe_description)/inertia/F12.xacro"/>
	<xacro:include filename="$(find tobe_description)/inertia/F11.xacro"/>
	<xacro:include filename="$(find tobe_description)/inertia/upperarm.xacro"/>
	<xacro:include filename="$(find tobe_description)/inertia/upperleg.xacro"/>
	<xacro:include filename="$(find tobe_description)/inertia/L_Foot.xacro"/>
	<xacro:include filename="$(find tobe_description)/inertia/R_Foot.xacro"/>
	<xacro:include filename="$(find tobe_description)/inertia/L_lowerarm.xacro"/>
	<xacro:include filename="$(find tobe_description)/inertia/R_lowerarm.xacro"/>
	<xacro:include filename="$(find tobe_description)/inertia/L_Tibia.xacro"/>
	<xacro:include filename="$(find tobe_description)/inertia/R_Tibia.xacro"/>
	<xacro:include filename="$(find tobe_description)/inertia/L_hip-R_ankle.xacro"/>
	<xacro:include filename="$(find tobe_description)/inertia/R_hip-L_ankle.xacro"/>
	<xacro:include filename="$(find tobe_description)/inertia/Hips.xacro"/>

    <!-- Import gazebo_ros_control plugin -->
    <xacro:include filename="$(find tobe_description)/gazebo.xacro" ns="gazebo"/>

    <!--  <xacro:property name="pi" value="3.14159"/> -->
    <xacro:property name="cad_dir" value="file://$(find tobe_description)/assets/cad"/>

    <!-- Typically, STL/DAE model units are in mm, but RViz units are in m, hence models must be scaled down by 1000. -->
    <xacro:macro name="default_geometry" params="cad_file suffix:=_FCD-Conv_BDR-Col extension:=dae">
        <geometry>
            <mesh filename="${cad_dir}/${cad_file}${suffix}.${extension}" scale="0.001 0.001 0.001"/>
        </geometry>
    </xacro:macro>

    <xacro:macro name="z_rot">
        <axis xyz="0 0 1"/>
    </xacro:macro>

    <!-- Standard parts of Bioloid Comprehensive humanoid with 18 AX-12+ servos, which have been replaced in custom version -->
    <!--  When using this URDF, ensure a transform from odom to base_link is being published -->
    <!-- <xacro:include filename="$(find bioloid_typea_description)/std_parts.xacro" ns="std_parts"/> -->
    <xacro:include filename="$(find tobe_description)/std_parts.xacro"/>

    <!-- IMU -->
    <joint name="imu_to_base_joint" type="fixed">
        <axis xyz="1 0 0"/>
        <origin xyz="0 0 0.05" rpy="0 0 0"/>
        <parent link="base_link"/>
        <child link="imu_link"/>
    </joint>
    <link name="imu_link">
        <visual>
            <origin rpy="0 0 0" xyz="0 0 0"/>
            <geometry>
                <box size="0.04 0.02 0.005"/>
            </geometry>
            <material name="green">
                <color rgba="0.0 1.0 0.0 1.0"/>
            </material>
        </visual>
          <collision>
	    <origin rpy="0 0 0" xyz="0 0 0"/>
	        <geometry>
	        <box size=".01 .01 .01"/>
	        </geometry>
	    </collision>
	  <inertial>
	    <mass value="0.001"/>
	    <origin rpy="0 0 0" xyz="0 0 0"/>
	    <inertia ixx="0.0001" ixy="0" ixz="0" iyy="0.000001" iyz="0" izz="0.0001"/>
	  </inertial>
    </link>


<!-- JOINT DEFINITIONS -->
    <xacro:macro name="shoulder_swing_joint" params="prefix reflect">
        <joint name="${prefix}_shoulder_swing_joint" type="revolute">
            <parent link="torso_link"/>
            <origin xyz="0 ${reflect*(-0.032)} 0" rpy="${reflect*pi/2} ${((reflect+1)/2)*pi} 0"/>
            <xacro:z_rot/>
            <child link="${prefix}_shoulder_swing_link"/>
            <limit lower="-1" upper="${pi/2}" effort="2.8" velocity="1.0"/>
        </joint>
    </xacro:macro>
    <xacro:macro name="shoulder_lateral_joint" params="prefix reflect">
        <joint name="${prefix}_shoulder_lateral_joint" type="revolute">
            <parent link="${prefix}_shoulder_swing_link"/>
            <origin xyz="0 0.014 0.044" rpy="0 ${-pi/2} 0"/>
            <xacro:z_rot/>
            <child link="${prefix}_upper_arm_link"/>
            <limit lower="-1.5" upper="1.5" effort="2.8" velocity="1.0"/>
        </joint>
    </xacro:macro>
    <xacro:macro name="elbow_joint" params="prefix reflect">
        <joint name="${prefix}_elbow_joint" type="revolute">
            <parent link="${prefix}_upper_arm_link"/>
            <origin xyz="0 0.0675 0" rpy="0 ${-pi/2} ${pi}"/>
	    <axis xyz="0 0 1"/>
            <xacro:z_rot/>
            <child link="${prefix}_lower_arm_link"/>
            <limit lower="-1.77" upper="1.77" effort="2.8" velocity="1.0"/>
        </joint>
    </xacro:macro>
    <xacro:macro name="hand_joint" params="prefix">
        <joint name="${prefix}_hand_joint" type="fixed">
            <parent link="${prefix}_lower_arm_link"/>
            <origin xyz="0 0 0" rpy="0 0 0"/>
            <child link="${prefix}_hand_link"/>
        </joint>
    </xacro:macro>
    <xacro:macro name="hip_twist_joint" params="prefix reflect">
        <joint name="${prefix}_hip_twist_joint" type="revolute">
            <parent link="torso_link"/>
            <origin xyz="0 ${reflect*(-0.0385)} -0.0655" rpy="0 ${pi} ${reflect*pi/2}"/>
            <xacro:z_rot/>
            <child link="${prefix}_hip_twist_link"/>
            <limit lower="-0.5" upper="0.5" effort="10" velocity="5.6548668"/>
        </joint>
    </xacro:macro>
    <xacro:macro name="hip_lateral_joint" params="prefix reflect">
        <joint name="${prefix}_hip_lateral_joint" type="revolute">
            <parent link="${prefix}_hip_twist_link"/>
            <origin xyz="0 0 0.047" rpy="${reflect*-pi/2} 0 0"/>
            <xacro:z_rot/>
            <child link="${prefix}_hip_lateral_link"/>
            <limit lower="-0.8" upper="0.8" effort="10" velocity="5.6548668"/>
        </joint>
    </xacro:macro>
    <xacro:macro name="hip_swing_joint" params="prefix reflect">
        <joint name="${prefix}_hip_swing_joint" type="revolute">
            <parent link="${prefix}_hip_lateral_link"/>
            <origin xyz="0 ${reflect*-0.068} 0" rpy="${pi/2} 0 ${-pi/2}"/>
            <xacro:z_rot/>
            <child link="${prefix}_upper_leg_link"/>
	    <limit lower="-2" upper="2" effort="30" velocity="5.6548668"/> 
            <!--<limit lower="${-0.8*(reflect-1)-2}" upper="${-0.8*(reflect+1)+2}" effort="10" velocity="5.6548668"/> -->
        </joint>
    </xacro:macro>        
    <xacro:macro name="knee_joint" params="prefix reflect">
        <joint name="${prefix}_knee_joint" type="revolute">
            <parent link="${prefix}_upper_leg_link"/>
            <origin xyz="${reflect*0.065} 0.0145 0" rpy="0 0 0"/>
            <axis xyz="0 0 1"/>
            <child link="${prefix}_lower_leg_link"/>
            <limit lower="${-1+reflect}" upper="${1+reflect}" effort="10" velocity="5.6548668"/>
        </joint>
    </xacro:macro>
    <xacro:macro name="ankle_swing_joint" params="prefix reflect">
        <joint name="${prefix}_ankle_swing_joint" type="revolute">
            <parent link="${prefix}_lower_leg_link"/>
            <origin xyz="${reflect*0.062} -0.0145 0" rpy="${pi} 0 0"/>
            <xacro:z_rot/>
            <child link="${prefix}_ankle_swing_link"/>
            <limit lower="${0.8*(reflect+1)-2}" upper="${0.8*(reflect-1)+2}" effort="10" velocity="5.6548668"/>
        </joint>
    </xacro:macro>
   <xacro:macro name="ankle_lateral_joint" params="prefix reflect">
        <joint name="${prefix}_ankle_lateral_joint" type="revolute">
            <parent link="${prefix}_ankle_swing_link"/>
            <origin xyz="${reflect*0.045} 0 -0.012" rpy="${-pi/2} 0 0"/>
            <xacro:z_rot/>
            <child link="${prefix}_ankle_lateral_link"/>
            <limit lower="-0.8" upper="0.8" effort="10" velocity="5.6548668"/>
        </joint>
    </xacro:macro>
    <xacro:macro name="foot_joint" params="prefix reflect">
        <joint name="${prefix}_foot_joint" type="fixed">
            <parent link="${prefix}_ankle_lateral_link"/>
            <origin xyz="0 -0.004 0.01" rpy="0 0 0"/>
            <child link="${prefix}_foot_link"/>
        </joint>
        <gazebo reference="${prefix}_foot_link">
            <mu1>1</mu1> <!-- 9000 -->
            <mu2>1</mu2> <!-- 9000 -->
            <kp>1000000.0</kp>
            <kd>10.0</kd>
            <minDepth>0.001</minDepth>
            <maxContacts>1</maxContacts>
        </gazebo>
    </xacro:macro>

    <!-- Leg links -->
    <xacro:hip_twist_joint prefix="r" reflect="1"/>
    <link name="r_hip_twist_link">
        <visual>
            <xacro:default_geometry cad_file="FP04-F2"/>
            <origin xyz="0 0 0.047" rpy="${pi} 0 ${pi/2}"/>
        </visual>
        <collision name="r_hip_twist_collision">
            <origin xyz="0.0008 0 0.041"/>
            <geometry>
                <box size="0.029 0.083 0.0405"/>
            </geometry>
        </collision>
        <xacro:hip_twist_inertial/>
    </link>

    <xacro:hip_twist_joint prefix="l" reflect="-1"/>
    <link name="l_hip_twist_link">
        <visual>
            <xacro:default_geometry cad_file="FP04-F2"/>
            <origin xyz="0 0 0.047" rpy="${pi} 0 ${pi/2}"/>
        </visual>
        <collision name="l_hip_twist_collision">
            <origin xyz="0.0008 0 0.041"/>
            <geometry>
                <box size="0.029 0.083 0.0405"/>
            </geometry>
        </collision>
        <xacro:hip_twist_inertial/>
    </link>


    <xacro:hip_lateral_joint prefix="r" reflect="1"/>
    <link name="r_hip_lateral_link">
        <!-- Motor 9[r]  -->
        <visual>
            <xacro:default_geometry cad_file="AX-12"/>
            <origin xyz="0 0 0" rpy="0 ${pi} 0"/>
        </visual>
        <visual>
            <xacro:default_geometry cad_file="FP04-F3"/>
            <origin xyz="0 -0.042 0" rpy="0 ${pi} 0"/>
        </visual>
        <visual>
            <xacro:default_geometry cad_file="FP04-F2"/>
            <origin xyz="0 -0.068 0" rpy="${-pi/2} 0 0"/>
        </visual>
        <collision name="r_hip_lateral_collision">
            <origin xyz="0 -0.0135 -0.0153"/>
            <geometry>
                <box size="0.04 0.051 0.0721"/>
            </geometry>
        </collision>
        <xacro:hip_lateral_right_inertial/>
    </link>

    <xacro:hip_lateral_joint prefix="l" reflect="-1"/>
    <link name="l_hip_lateral_link">
        <!-- Motor 10[l] -->
        <visual>
            <xacro:default_geometry cad_file="AX-12"/>
            <origin xyz="0 0 0" rpy="0 ${pi} ${pi}"/>
        </visual>
        <visual>
            <xacro:default_geometry cad_file="FP04-F3"/>
            <origin xyz="0 0.042 0" rpy="0 0 ${pi}"/>
        </visual>
        <visual>
            <xacro:default_geometry cad_file="FP04-F2"/>
            <origin xyz="0 0.068 0" rpy="${-pi/2} 0 ${pi}"/>
        </visual>
        <collision name="l_hip_lateral_collision">
            <origin xyz="0 -0.0135 -0.0153"/>
            <geometry>
                <box size="0.04 0.051 0.0721"/>
            </geometry>
        </collision>
        <xacro:hip_lateral_left_inertial/>
    </link>

    <xacro:hip_swing_joint prefix="r" reflect="1"/>
    <link name="r_upper_leg_link">
         <!-- Motor 11[r] -->
        <visual>
            <xacro:default_geometry cad_file="AX-12"/>
            <origin xyz="0 0 0" rpy="0 0 ${pi/2}"/>
        </visual>
        <visual>
            <xacro:default_geometry cad_file="FP04-F3"/>
            <origin xyz="0.042 0 0" rpy="0 0 ${pi/2}"/>
        </visual>
        <visual>
            <xacro:default_geometry cad_file="FP04-F1"/>
            <origin xyz="0.065 0.0145 0" rpy="${pi} ${pi/2} 0"/>
        </visual>
        <collision name="r_upper_leg_proximal_collision">
            <origin xyz="0.0214 0 0"/>
            <geometry>
                <box size="0.065 0.03 0.049"/>
            </geometry>
        </collision>
        <collision name="r_upper_leg_distal_collision">
            <origin xyz="0.0675 0.0065 0"/>
            <geometry>
                <box size="0.04 0.0371 0.049"/>
            </geometry>
        </collision>
        <xacro:upperleg_inertial/>
    </link>

    <xacro:hip_swing_joint prefix="l" reflect="-1"/>    
    <link name="l_upper_leg_link">
         <!-- Motor 12[l] -->
        <visual>
            <xacro:default_geometry cad_file="AX-12"/>
            <origin xyz="0 0 0" rpy="0 0 ${-pi/2}"/>
        </visual>
        <visual>
            <xacro:default_geometry cad_file="FP04-F3"/>
            <origin xyz="-0.042 0 0" rpy="0 0 ${-pi/2}"/>
        </visual>
        <visual>
            <xacro:default_geometry cad_file="FP04-F1"/>
            <origin xyz="-0.065 0.0145 0" rpy="${pi} ${-pi/2} 0"/>
        </visual>
        <collision name="l_upper_leg_proximal_collision">
            <origin xyz="0.0214 0 0"/>
            <geometry>
                <box size="0.065 0.03 0.049"/>
            </geometry>
        </collision>
        <collision name="l_upper_leg_distal_collision">
            <origin xyz="0.0675 0.0065 0"/>
            <geometry>
                <box size="0.04 0.0371 0.049"/>
            </geometry>
        </collision>
        <xacro:upperleg_inertial/>
    </link>

<!-- KNEES -->

    <xacro:knee_joint prefix="r" reflect="1"/>
    <link name="r_lower_leg_link">
        <!-- Motor 13[r] -->
        <visual>
            <xacro:default_geometry cad_file="AX-12"/>
            <origin xyz="0 0 0" rpy="0 0 0"/>
        </visual>
        <visual>
            <xacro:default_geometry cad_file="FP04-F3"/>
            <origin xyz="0.02 -0.0145 0" rpy="0 0 ${pi/2}"/>
        </visual>
        <visual>
            <xacro:default_geometry cad_file="FP04-F3"/>
            <origin xyz="0.02 -0.0145 0" rpy="0 0 ${-pi/2}"/>
        </visual>
        <visual>
            <xacro:default_geometry cad_file="AX-12"/>
            <origin xyz="0.062 -0.0145 0" rpy=" 0 ${pi} ${-pi/2}"/>
        </visual>
        <collision name="r_lower_leg_proximal_collision">
            <origin xyz="0 -0.0135 0"/>
            <geometry>
                <box size="0.033 0.051 0.044"/>
            </geometry>
        </collision>
        <collision name="r_lower_leg_distal_collision">
            <origin xyz="0.0492 -0.0145 0"/>
            <geometry>
                <box size="0.067 0.03 0.049"/>
            </geometry>
        </collision>
        <xacro:tibia_right_inertial/>
    </link>

    <xacro:knee_joint prefix="l" reflect="-1"/>
    <link name="l_lower_leg_link">
        <!-- Motor 14[l] -->
        <visual>
            <xacro:default_geometry cad_file="AX-12"/>
            <origin xyz="0 0 0" rpy="0 0 0"/>
        </visual>
        <visual>
            <xacro:default_geometry cad_file="FP04-F3"/>
            <origin xyz="-0.02 -0.0145 0" rpy="0 0 ${-pi/2}"/>
        </visual>
        <visual>
            <xacro:default_geometry cad_file="FP04-F3"/>
            <origin xyz="-0.02 -0.0145 0" rpy="0 0 ${pi/2}"/>
        </visual>
        <visual>
            <xacro:default_geometry cad_file="AX-12"/>
            <origin xyz="-0.062 -0.0145 0" rpy=" 0 ${pi} ${pi/2}"/>
        </visual>
        <collision name="l_lower_leg_proximal_collision">
            <origin xyz="0 -0.0135 0"/>
            <geometry>
                <box size="0.033 0.051 0.044"/>
            </geometry>
        </collision>
        <collision name="l_lower_leg_distal_collision">
            <origin xyz="0.0492 -0.0145 0"/>
            <geometry>
                <box size="0.067 0.03 0.049"/>
            </geometry>
        </collision>
        <xacro:tibia_left_inertial/>
    </link>

<!-- ANKLES -->

    <xacro:ankle_swing_joint prefix="r" reflect="1"/>
    <link name="r_ankle_swing_link">
        <!-- Motor 15[r]  -->
        <visual>
            <xacro:default_geometry cad_file="FP04-F2"/>
            <origin xyz="-0.0005 0 0" rpy="0 ${pi/2} 0"/>
        </visual>
        <visual>
            <xacro:default_geometry cad_file="FP04-F3"/>
            <origin xyz="0.0255 0 0" rpy="0 ${-pi/2} ${-pi/2}"/>
        </visual>
        <collision name="r_ankle_swing_collision">
            <origin xyz="-0.0135 -0.0167 0"/>
            <geometry>
                <box size="0.051 0.0721 0.04"/>
            </geometry>
        </collision>
        <xacro:lowerleg_right_inertial/>
    </link>

    <xacro:ankle_swing_joint prefix="l" reflect="-1"/>
    <link name="l_ankle_swing_link">
        <!-- Motor 16[l] -->
        <visual>
            <xacro:default_geometry cad_file="FP04-F2"/>
            <origin xyz="0.0005 0 0" rpy="0 ${-pi/2} 0"/>
        </visual>
        <visual>
            <xacro:default_geometry cad_file="FP04-F3"/>
            <origin xyz="-0.0255 0 0" rpy="0 ${pi/2} ${pi/2}"/>
        </visual>
        <collision name="l_ankle_swing_collision">
            <origin xyz="-0.0135 -0.0167 0"/>
            <geometry>
                <box size="0.051 0.0721 0.04"/>
            </geometry>
        </collision>
        <xacro:lowerleg_left_inertial/>
    </link>

    <xacro:ankle_lateral_joint prefix="r" reflect="1"/>
    <link name="r_ankle_lateral_link">
 <!-- Motor 17[r] -->
        <visual>
            <xacro:default_geometry cad_file="AX-12"/>
            <origin xyz="0 0 0" rpy="0 0 0"/>
        </visual>
        <visual>
            <xacro:default_geometry cad_file="FP04-F2"/>
            <origin xyz="0 0 0" rpy="0 ${pi/2} 0"/>
        </visual>
        <collision name="r_ankle_lateral_collision">
            <origin xyz="0.009 0 -0.016"/>
            <geometry>
                <box size="0.0405 0.029 0.083"/>
            </geometry>
        </collision>
    </link>

     <xacro:ankle_lateral_joint prefix="l" reflect="-1"/>
     <link name="l_ankle_lateral_link">
 <!-- Motor 18[l] -->
        <visual>
            <xacro:default_geometry cad_file="AX-12"/>
            <origin xyz="0 0 0" rpy="0 0 0"/>
        </visual>
        <visual>
            <xacro:default_geometry cad_file="FP04-F2"/>
            <origin xyz="0 0 0" rpy="0 ${-pi/2} 0"/>
        </visual>
        <collision name="l_ankle_lateral_collision">
            <origin xyz="0.009 0 -0.016"/>
            <geometry>
                <box size="0.0405 0.029 0.083"/>
            </geometry>
        </collision>
    </link>

<!-- UPPER BODY -->

    <!-- Base -->
    <joint name="base_to_torso_joint" type="fixed">
        <parent link="base_link"/>
        <origin xyz="0 0 0" rpy="0 0 0"/>
        <child link="torso_link"/>
    </joint>
    <link name="base_link">
    </link>

    <!-- Torso to right shoulder -->
    <xacro:shoulder_swing_joint prefix="r" reflect="1"/>
    <link name="r_shoulder_swing_link">
        <visual>
            <xacro:default_geometry cad_file="FP04-F1"/>
            <origin xyz="0 0.014 0.044" rpy="0 ${pi} ${pi}"/>
        </visual>
        <collision name="r_shoulder_collision">
            <origin xyz="0 0.006 0.0375"/>
            <geometry>
                <box size="0.052 0.039 0.036"/>
            </geometry>
        </collision>
        <xacro:shoulder_right_inertial/>
    </link>

    <!-- Torso to left shoulder -->
    <xacro:shoulder_swing_joint prefix="l" reflect="-1"/>
    <link name="l_shoulder_swing_link">
        <visual>
            <xacro:default_geometry cad_file="FP04-F1"/>
            <origin xyz="0 0.014 0.044" rpy="0 ${pi} ${pi}"/>
        </visual>
        <collision name="l_shoulder_collision">
            <origin xyz="0 0.006 0.0375"/>
            <geometry>
                <box size="0.052 0.039 0.036"/>
            </geometry>
        </collision>
        <xacro:shoulder_left_inertial/>
    </link>

    <!-- Right shoulder to upper arm -->
    <xacro:shoulder_lateral_joint prefix="r" reflect="1"/>
    <link name="r_upper_arm_link">
        <visual>
            <xacro:default_geometry cad_file="AX-12"/>
            <origin xyz="0 0 0" rpy="0 0 ${pi}"/>
        </visual>
        <visual>
            <xacro:default_geometry cad_file="FP04-F3"/>
            <origin xyz="0 0.0415 0" rpy="0 0 ${pi}"/>
        </visual>
        <visual>
            <xacro:default_geometry cad_file="FP04-F2"/>
            <origin xyz="0 0.0675 0" rpy="${pi/2} 0 0"/>
        </visual>
        <collision name="r_upper arm_collision_proximal">
            <origin xyz="0.0148 0 0"/>
            <geometry>
                <box size="0.054 0.033 0.044"/>
            </geometry>
        </collision>
        <collision name="r_upper arm_collision_distal">
            <origin xyz="0.0555 0 0"/>
            <geometry>
                <box size="0.047 0.033 0.052"/>
            </geometry>
        </collision>
        <xacro:upperarm_right_inertial/>
    </link>

    <!-- Left shoulder to upper arm -->
    <xacro:shoulder_lateral_joint prefix="l" reflect="-1"/>
    <link name="l_upper_arm_link">
        <visual>
            <xacro:default_geometry cad_file="AX-12"/>
            <origin xyz="0 0 0" rpy="0 ${pi} ${pi}"/>
        </visual>
        <visual>
            <xacro:default_geometry cad_file="FP04-F3"/>
            <origin xyz="0 0.0415 0" rpy="0 0 ${pi}"/>
        </visual>
        <visual>
            <xacro:default_geometry cad_file="FP04-F2"/>
            <origin xyz="0 0.0675 0" rpy="${pi/2} 0 0"/>
        </visual>
        <collision name="l_upper arm_collision_proximal">
            <origin xyz="0.0148 0 0"/>
            <geometry>
                <box size="0.054 0.033 0.044"/>
            </geometry>
        </collision>
        <collision name="l_upper arm_collision_distal">
            <origin xyz="0.0555 0 0"/>
            <geometry>
                <box size="0.047 0.033 0.052"/>
            </geometry>
        </collision>
        <xacro:upperarm_left_inertial/>
    </link>

    <!-- Right upper arm to lower arm -->
    <xacro:elbow_joint prefix="r" reflect="1"/>
    <link name="r_lower_arm_link">
        <!-- Motor 5 -->
        <visual>
            <xacro:default_geometry cad_file="AX-12"/>
            <origin xyz="0 0 0" rpy="0 0 0"/>
        </visual>
        <visual>
            <xacro:default_geometry cad_file="FP04-F3"/>
            <origin xyz="0 -0.0415 0" rpy="0 0 0"/>
        </visual>
        <collision name="r_lower_arm_collision">
            <origin xyz="0 0.017 0"/>
            <geometry>
                <box size="0.058 0.033 0.044"/>
            </geometry>
        </collision>
        <xacro:lowerarm_right_inertial/>
    </link>

    <!-- Left upper arm to lower arm -->
    <xacro:elbow_joint prefix="l" reflect="-1"/>
    <link name="l_lower_arm_link">
        <!-- Motor 6 -->
        <visual>
            <xacro:default_geometry cad_file="AX-12"/>
            <origin xyz="0 0 0" rpy="0 0 0"/>
        </visual>
        <visual>
            <xacro:default_geometry cad_file="FP04-F3"/>
            <origin xyz="0 -0.0415 0" rpy="0 0 0"/>
        </visual>
        <collision name="l_lower_arm_collision">
            <origin xyz="0 0.017 0"/>
            <geometry>
                <box size="0.058 0.033 0.044"/>
            </geometry>
        </collision>
        <xacro:upperarm_left_inertial/>
    </link>

    <!-- Right lower arm to hand -->
    <xacro:hand_joint prefix="r"/>
    <link name="r_hand_link">
        <visual>
            <xacro:default_geometry cad_file="FP04-F11"/>
            <origin xyz="0 -0.0415 0" rpy="${pi/2} 0 0"/>
        </visual>
        <collision name="r_palm_collision">
            <origin xyz="0.039 0 0"/>
            <geometry>
                <box size="0.0131 0.0265 0.044"/>
            </geometry>
        </collision>
        <collision name="r_fingers_collision">
            <origin xyz="0.0701 -0.0077 0"/>
            <geometry>
                <box size="0.0575 0.0175 0.035"/>
            </geometry>
        </collision>
        <xacro:arm_right_inertial/>
    </link>

    <!-- Left lower arm to hand -->
    <xacro:hand_joint prefix="l"/>
    <link name="l_hand_link">
        <visual>
            <xacro:default_geometry cad_file="FP04-F11"/>
            <origin xyz="0 -0.0415 0" rpy="${pi/2} 0 0"/>
        </visual>
        <collision name="l_palm_collision">
            <origin xyz="0.039 0 0"/>
            <geometry>
                <box size="0.0131 0.0265 0.044"/>
            </geometry>
        </collision>
        <collision name="l_fingers_collision">
            <origin xyz="0.0701 -0.0077 0"/>
            <geometry>
                <box size="0.0575 0.0175 0.035"/>
            </geometry>
        </collision>
        <xacro:arm_left_inertial/>
    </link>

    <!-- Right ankle lateral to foot -->
    <xacro:foot_joint prefix="r" reflect="1"/>

    <!-- Left ankle lateral to foot -->
    <xacro:foot_joint prefix="l" reflect="-1"/>



    <xacro:macro name="shoulder_swing_joint_gazebo" params="prefix">
        <transmission name="${prefix}_shoulder_swing_joint_tran">
            <type>transmission_interface/SimpleTransmission</type>
            <joint name="${prefix}_shoulder_swing_joint">
                <hardwareInterface>hardware_interface/EffortJointInterface</hardwareInterface>
            </joint>
            <actuator name="${prefix}_shoulder_swing_joint_motor">
                <hardwareInterface>hardware_interface/EffortJointInterface</hardwareInterface>
                <mechanicalReduction>1</mechanicalReduction>
            </actuator>
        </transmission>
    </xacro:macro>
    <xacro:macro name="shoulder_lateral_joint_gazebo" params="prefix">
        <transmission name="${prefix}_shoulder_lateral_joint_tran">
            <type>transmission_interface/SimpleTransmission</type>
            <joint name="${prefix}_shoulder_lateral_joint">
                <hardwareInterface>hardware_interface/EffortJointInterface</hardwareInterface>
            </joint>
            <actuator name="${prefix}_shoulder_lateral_joint_motor">
                <hardwareInterface>hardware_interface/EffortJointInterface</hardwareInterface>
                <mechanicalReduction>1</mechanicalReduction>
            </actuator>
        </transmission>
    </xacro:macro>
    <xacro:macro name="elbow_joint_gazebo" params="prefix">
        <transmission name="${prefix}_elbow_joint_tran">
            <type>transmission_interface/SimpleTransmission</type>
            <joint name="${prefix}_elbow_joint">
                <hardwareInterface>hardware_interface/EffortJointInterface</hardwareInterface>
            </joint>
            <actuator name="${prefix}_elbow_joint_motor">
                <hardwareInterface>EffortJointInterface</hardwareInterface>
                <mechanicalReduction>1</mechanicalReduction>
            </actuator>
        </transmission>
    </xacro:macro>
    <xacro:macro name="hip_twist_joint_gazebo" params="prefix">
        <transmission name="${prefix}_hip_twist_joint_tran">
            <type>transmission_interface/SimpleTransmission</type>
            <joint name="${prefix}_hip_twist_joint">
                <hardwareInterface>hardware_interface/EffortJointInterface</hardwareInterface>
            </joint>
            <actuator name="${prefix}_hip_twist_joint_motor">
                <hardwareInterface>hardware_interface/EffortJointInterface</hardwareInterface>
                <mechanicalReduction>1</mechanicalReduction>
            </actuator>
        </transmission>
    </xacro:macro>
    <xacro:macro name="hip_lateral_joint_gazebo" params="prefix">
        <transmission name="${prefix}_hip_lateral_joint_tran">
            <type>transmission_interface/SimpleTransmission</type>
            <joint name="${prefix}_hip_lateral_joint">
                <hardwareInterface>hardware_interface/EffortJointInterface</hardwareInterface>
            </joint>
            <actuator name="${prefix}_hip_lateral_joint_motor">
                <hardwareInterface>hardware_interface/EffortJointInterface</hardwareInterface>
                <mechanicalReduction>1</mechanicalReduction>
            </actuator>
        </transmission>
    </xacro:macro>
    <xacro:macro name="hip_swing_joint_gazebo" params="prefix">
        <transmission name="${prefix}_hip_swing_joint_tran">
            <type>transmission_interface/SimpleTransmission</type>
            <joint name="${prefix}_hip_swing_joint">
                <hardwareInterface>hardware_interface/EffortJointInterface</hardwareInterface>
            </joint>
            <actuator name="${prefix}_hip_swing_joint_motor">
                <hardwareInterface>hardware_interface/EffortJointInterface</hardwareInterface>
                <mechanicalReduction>1</mechanicalReduction>
            </actuator>
        </transmission>
    </xacro:macro>
    <xacro:macro name="knee_joint_gazebo" params="prefix">
        <transmission name="${prefix}_knee_joint_tran">
            <type>transmission_interface/SimpleTransmission</type>
            <joint name="${prefix}_knee_joint">
                <hardwareInterface>hardware_interface/EffortJointInterface</hardwareInterface>
            </joint>
            <actuator name="${prefix}_knee_joint_motor">
                <hardwareInterface>hardware_interface/EffortJointInterface</hardwareInterface>
                <mechanicalReduction>1</mechanicalReduction>
            </actuator>
        </transmission>
    </xacro:macro>
    <xacro:macro name="ankle_swing_joint_gazebo" params="prefix">
        <transmission name="${prefix}_ankle_swing_joint_tran">
            <type>transmission_interface/SimpleTransmission</type>
            <joint name="${prefix}_ankle_swing_joint">
                <hardwareInterface>hardware_interface/EffortJointInterface</hardwareInterface>
            </joint>
            <actuator name="${prefix}_ankle_swing_joint_motor">
                <hardwareInterface>hardware_interface/EffortJointInterface</hardwareInterface>
                <mechanicalReduction>1</mechanicalReduction>
            </actuator>
        </transmission>
    </xacro:macro>
    <xacro:macro name="ankle_lateral_joint_gazebo" params="prefix">
        <transmission name="${prefix}_ankle_lateral_joint_tran">
            <type>transmission_interface/SimpleTransmission</type>
            <joint name="${prefix}_ankle_lateral_joint">
                <hardwareInterface>hardware_interface/EffortJointInterface</hardwareInterface>
            </joint>
            <actuator name="${prefix}_ankle_lateral_joint_motor">
                <hardwareInterface>hardware_interface/EffortJointInterface</hardwareInterface>
                <mechanicalReduction>1</mechanicalReduction>
            </actuator>
        </transmission>
    </xacro:macro>

    <xacro:shoulder_swing_joint_gazebo prefix="r"/>
    <xacro:shoulder_swing_joint_gazebo prefix="l"/>
    <xacro:shoulder_lateral_joint_gazebo prefix="r"/>
    <xacro:shoulder_lateral_joint_gazebo prefix="l"/>
    <xacro:elbow_joint_gazebo prefix="r"/>
    <xacro:elbow_joint_gazebo prefix="l"/>
    <xacro:hip_twist_joint_gazebo prefix="r"/>
    <xacro:hip_twist_joint_gazebo prefix="l"/>
    <xacro:hip_lateral_joint_gazebo prefix="r"/>
    <xacro:hip_lateral_joint_gazebo prefix="l"/>
    <xacro:hip_swing_joint_gazebo prefix="r"/>
    <xacro:hip_swing_joint_gazebo prefix="l"/>
    <xacro:knee_joint_gazebo prefix="r"/>
    <xacro:knee_joint_gazebo prefix="l"/>
    <xacro:ankle_swing_joint_gazebo prefix="r"/>
    <xacro:ankle_swing_joint_gazebo prefix="l"/>
    <xacro:ankle_lateral_joint_gazebo prefix="r"/>
    <xacro:ankle_lateral_joint_gazebo prefix="l"/>

</robot>

