<?xml version="1.0" ?>
<!-- =================================================================================== -->
<!-- |    This document was autogenerated by xacro from tobe.xacro                     | -->
<!-- |    EDITING THIS FILE BY HAND IS NOT RECOMMENDED                                 | -->
<!-- =================================================================================== -->
<robot name="tobe">
  <gazebo>
    <plugin filename="libgazebo_ros_control.so" name="gazebo_ros_control">
      <robotNamespace>/tobe</robotNamespace>
      <robotSimType>gazebo_ros_control/DefaultRobotHWSim</robotSimType>
    </plugin>
    <plugin filename="libgazebo_ros_imu.so" name="imu_plugin">
      <alwaysOn>true</alwaysOn>
      <bodyName>imu_link</bodyName>
      <topicName>/tobe/imu</topicName>
      <serviceName>imu_service</serviceName>
      <gaussianNoise>0.0</gaussianNoise>
      <updateRate>50.0</updateRate>
      <visualize>true</visualize>
    </plugin>
  </gazebo>
  <!-- Torso -->
  <link name="torso_link">
    <visual>
      <geometry>
        <mesh filename="file:///home/jerry/tobesim/catkin_ws/src/tobe_description/assets/cad/BPF-CHEST-F_FCD-Conv_BDR-Col.dae" scale="0.001 0.001 0.001"/>
      </geometry>
      <origin rpy="1.5707963267948966 0 1.5707963267948966"/>
    </visual>
    <visual>
      <geometry>
        <mesh filename="file:///home/jerry/tobesim/catkin_ws/src/tobe_description/assets/cad/BPF-CHEST-B_FCD-Conv_BDR-Col.dae" scale="0.001 0.001 0.001"/>
      </geometry>
      <origin rpy="1.5707963267948966 0 1.5707963267948966"/>
    </visual>
    <visual>
      <geometry>
        <mesh filename="file:///home/jerry/tobesim/catkin_ws/src/tobe_description/assets/cad/CM-5_FCD-Conv_BDR-Col.dae" scale="0.001 0.001 0.001"/>
      </geometry>
      <origin rpy="0 3.141592653589793 1.5707963267948966" xyz="-0.032 0 -0.015"/>
    </visual>
    <!-- Sensor 100 -->
    <visual>
      <geometry>
        <mesh filename="file:///home/jerry/tobesim/catkin_ws/src/tobe_description/assets/cad/AX-S1_FCD-Conv_BDR-Col.dae" scale="0.001 0.001 0.001"/>
      </geometry>
      <origin rpy="-1.5707963267948966 0 -1.5707963267948966" xyz="0 0 0.025"/>
    </visual>
    <!-- Motor 1 -->
    <visual>
      <geometry>
        <mesh filename="file:///home/jerry/tobesim/catkin_ws/src/tobe_description/assets/cad/AX-12_FCD-Conv_BDR-Col.dae" scale="0.001 0.001 0.001"/>
      </geometry>
      <origin rpy="1.5707963267948966 0 0" xyz="0 -0.032 0"/>
    </visual>
    <visual>
      <geometry>
        <mesh filename="file:///home/jerry/tobesim/catkin_ws/src/tobe_description/assets/cad/FP04-F3_FCD-Conv_BDR-Col.dae" scale="0.001 0.001 0.001"/>
      </geometry>
      <origin rpy="3.141592653589793 -1.5707963267948966 1.5707963267948966" xyz="-0.019 -0.032 -0.0145"/>
    </visual>
    <!-- Motor 2 -->
    <visual>
      <geometry>
        <mesh filename="file:///home/jerry/tobesim/catkin_ws/src/tobe_description/assets/cad/AX-12_FCD-Conv_BDR-Col.dae" scale="0.001 0.001 0.001"/>
      </geometry>
      <origin rpy="1.5707963267948966 0 3.141592653589793" xyz="0 0.032 0"/>
    </visual>
    <visual>
      <geometry>
        <mesh filename="file:///home/jerry/tobesim/catkin_ws/src/tobe_description/assets/cad/FP04-F3_FCD-Conv_BDR-Col.dae" scale="0.001 0.001 0.001"/>
      </geometry>
      <origin rpy="3.141592653589793 -1.5707963267948966 1.5707963267948966" xyz="-0.019 0.032 -0.0145"/>
    </visual>
    <visual>
      <geometry>
        <mesh filename="file:///home/jerry/tobesim/catkin_ws/src/tobe_description/assets/cad/FP04-F3_FCD-Conv_BDR-Col.dae" scale="0.001 0.001 0.001"/>
      </geometry>
      <origin rpy="0 0 1.5707963267948966" xyz="0.0175 0 -0.0655"/>
    </visual>
    <visual>
      <geometry>
        <mesh filename="file:///home/jerry/tobesim/catkin_ws/src/tobe_description/assets/cad/FP04-F3_FCD-Conv_BDR-Col.dae" scale="0.001 0.001 0.001"/>
      </geometry>
      <origin rpy="0 0 -1.5707963267948966" xyz="-0.0175 0 -0.0655"/>
    </visual>
    <!-- Motor 7 -->
    <visual>
      <geometry>
        <mesh filename="file:///home/jerry/tobesim/catkin_ws/src/tobe_description/assets/cad/AX-12_FCD-Conv_BDR-Col.dae" scale="0.001 0.001 0.001"/>
      </geometry>
      <origin rpy="0 3.141592653589793 3.141592653589793" xyz="0 -0.0385 -0.0655"/>
    </visual>
    <!-- Motor 8 -->
    <visual>
      <geometry>
        <mesh filename="file:///home/jerry/tobesim/catkin_ws/src/tobe_description/assets/cad/AX-12_FCD-Conv_BDR-Col.dae" scale="0.001 0.001 0.001"/>
      </geometry>
      <origin rpy="0 3.141592653589793 0" xyz="0 0.0385 -0.0655"/>
    </visual>
    <collision name="head_collision">
      <origin xyz="-0.0122 0 0.035"/>
      <geometry>
        <box size="0.054 0.033 0.044"/>
      </geometry>
    </collision>
    <collision name="torso_collision_top">
      <origin xyz="-0.019 0 -0.015"/>
      <geometry>
        <box size="0.0905 0.103 0.0635"/>
      </geometry>
    </collision>
    <collision name="torso_collision_bottom">
      <origin xyz="-0.00625 0 -0.0648"/>
      <geometry>
        <box size="0.065 0.099 0.043"/>
      </geometry>
    </collision>
    <inertial>
      <mass value="3.4770266466"/>
      <origin xyz="0.0162019036 0.0049844800 0.0038595353"/>
      <inertia ixx="0.9787053684" ixy="0.0543464614" ixz="-0.0262073548" iyy="0.9730952674" iyz="0.0198675713" izz="0.9352573858"/>
    </inertial>
    <!--
        <inertial>
            <origin xyz="-0.003053 -0.038651 -0.019268" />
            <mass value="0.97559947"/>
            <inertia ixx="3.1081800"  ixy="-0.25460189"  ixz="2.0318174" iyy="6.3787776" iyz="0.16417863" izz="5.3316425" />
        </inertial>
        -->
  </link>
  <!-- Right foot -->
  <link name="r_foot_link">
    <visual>
      <geometry>
        <mesh filename="file:///home/jerry/tobesim/catkin_ws/src/tobe_description/assets/cad/FP04-F12_FCD-Conv_BDR-Col.dae" scale="0.001 0.001 0.001"/>
      </geometry>
      <origin rpy="0 1.5707963267948966 -1.5707963267948966" xyz="0.0235 0 0"/>
    </visual>
    <collision name="r_foot_collision">
      <origin xyz="0.0277 0 0"/>
      <geometry>
        <box size="0.009 0.061 0.101"/>
      </geometry>
    </collision>
    <inertial>
      <mass value="0.1867801099"/>
      <origin xyz="-0.0055676472 0.0034398816 0.0028465215"/>
      <inertia ixx="0.0123442309" ixy="-0.0013373380" ixz="-0.0014042040" iyy="0.0351609327" iyz="0.0011525105" izz="0.0411013075"/>
    </inertial>
    <!--
        <inertial>
            <origin xyz="-0.025995 -0.009506 -0.000503" />
            <mass value="0.0794462"/>
            <inertia ixx="0.12079175"  ixy="-0.00079781067"  ixz="-0.00039322246" iyx="-0.00079781067" iyy="0.10885465" iyz="0.0070770117" izx="-0.00039322246" izy="0.0070770117" izz="0.041871103" />
        </inertial>
        -->
  </link>
  <!-- Left foot -->
  <link name="l_foot_link">
    <visual>
      <geometry>
        <mesh filename="file:///home/jerry/tobesim/catkin_ws/src/tobe_description/assets/cad/FP04-F12_FCD-Conv_BDR-Col.dae" scale="0.001 0.001 0.001"/>
      </geometry>
      <origin rpy="3.141592653589793 1.5707963267948966 -1.5707963267948966" xyz="-0.0235 0 0"/>
    </visual>
    <collision name="l_foot_collision">
      <origin xyz="-0.0277 0 0"/>
      <geometry>
        <box size="0.009 0.061 0.101"/>
      </geometry>
    </collision>
    <inertial>
      <mass value="0.1867801099"/>
      <origin xyz="-0.0055676472 -0.0035014440 0.0028465215"/>
      <inertia ixx="0.0123437897" ixy="0.0013329200" ixz="-0.0014042040" iyy="0.0351609292" iyz="-0.0011492661" izz="0.0411008628"/>
    </inertial>
    <!--
        <inertial>
            <origin xyz="-0.025995 -0.009506 -0.000503" />
            <mass value="0.0794462"/>
            <inertia ixx="0.12079175"  ixy="-0.00079781067"  ixz="-0.00039322246" iyx="-0.00079781067" iyy="0.10885465" iyz="0.0070770117" izx="-0.00039322246" izy="0.0070770117" izz="0.041871103" />
        </inertial>
        -->
  </link>
  <!-- IMU -->
  <joint name="imu_to_base_joint" type="fixed">
    <axis xyz="1 0 0"/>
    <origin rpy="0 0 0" xyz="0 0 0.05"/>
    <parent link="base_link"/>
    <child link="imu_link"/>
  </joint>
  <link name="imu_link">
    <visual>
      <origin rpy="0 0 0" xyz="0 0 0"/>
      <geometry>
        <box size="0.04 0.02 0.005"/>
      </geometry>
      <material name="green">
        <color rgba="0.0 1.0 0.0 1.0"/>
      </material>
    </visual>
    <collision>
      <origin rpy="0 0 0" xyz="0 0 0"/>
      <geometry>
        <box size=".01 .01 .01"/>
      </geometry>
    </collision>
    <inertial>
      <mass value="0.001"/>
      <origin rpy="0 0 0" xyz="0 0 0"/>
      <inertia ixx="0.0001" ixy="0" ixz="0" iyy="0.000001" iyz="0" izz="0.0001"/>
    </inertial>
  </link>
  <joint name="r_hip_twist_joint" type="revolute">
    <parent link="torso_link"/>
    <origin rpy="0 3.141592653589793 1.5707963267948966" xyz="0 -0.0385 -0.0655"/>
    <axis xyz="0 0 1"/>
    <child link="r_hip_twist_link"/>
    <limit effort="10" lower="-0.5" upper="0.5" velocity="5.6548668"/>
  </joint>
  <link name="r_hip_twist_link">
    <visual>
      <geometry>
        <mesh filename="file:///home/jerry/tobesim/catkin_ws/src/tobe_description/assets/cad/FP04-F2_FCD-Conv_BDR-Col.dae" scale="0.001 0.001 0.001"/>
      </geometry>
      <origin rpy="3.141592653589793 0 1.5707963267948966" xyz="0 0 0.047"/>
    </visual>
    <collision name="r_hip_twist_collision">
      <origin xyz="0.0008 0 0.041"/>
      <geometry>
        <box size="0.029 0.083 0.0405"/>
      </geometry>
    </collision>
    <inertial>
      <mass value="0.0755193623"/>
      <origin xyz="0.0005416307 -0.0000009200 0.0190685105"/>
      <inertia ixx="0.0082750315" ixy="-0.0000001051" ixz="0.0002681193" iyy="0.0194814984" iyz="-0.0000005502" izz="0.0133677616"/>
    </inertial>
  </link>
  <joint name="l_hip_twist_joint" type="revolute">
    <parent link="torso_link"/>
    <origin rpy="0 3.141592653589793 -1.5707963267948966" xyz="0 0.0385 -0.0655"/>
    <axis xyz="0 0 1"/>
    <child link="l_hip_twist_link"/>
    <limit effort="10" lower="-0.5" upper="0.5" velocity="5.6548668"/>
  </joint>
  <link name="l_hip_twist_link">
    <visual>
      <geometry>
        <mesh filename="file:///home/jerry/tobesim/catkin_ws/src/tobe_description/assets/cad/FP04-F2_FCD-Conv_BDR-Col.dae" scale="0.001 0.001 0.001"/>
      </geometry>
      <origin rpy="3.141592653589793 0 1.5707963267948966" xyz="0 0 0.047"/>
    </visual>
    <collision name="l_hip_twist_collision">
      <origin xyz="0.0008 0 0.041"/>
      <geometry>
        <box size="0.029 0.083 0.0405"/>
      </geometry>
    </collision>
    <inertial>
      <mass value="0.0755193623"/>
      <origin xyz="0.0005416307 -0.0000009200 0.0190685105"/>
      <inertia ixx="0.0082750315" ixy="-0.0000001051" ixz="0.0002681193" iyy="0.0194814984" iyz="-0.0000005502" izz="0.0133677616"/>
    </inertial>
  </link>
  <joint name="r_hip_lateral_joint" type="revolute">
    <parent link="r_hip_twist_link"/>
    <origin rpy="-1.5707963267948966 0 0" xyz="0 0 0.047"/>
    <axis xyz="0 0 1"/>
    <child link="r_hip_lateral_link"/>
    <limit effort="10" lower="-0.8" upper="0.8" velocity="5.6548668"/>
  </joint>
  <link name="r_hip_lateral_link">
    <!-- Motor 9[r]  -->
    <visual>
      <geometry>
        <mesh filename="file:///home/jerry/tobesim/catkin_ws/src/tobe_description/assets/cad/AX-12_FCD-Conv_BDR-Col.dae" scale="0.001 0.001 0.001"/>
      </geometry>
      <origin rpy="0 3.141592653589793 0" xyz="0 0 0"/>
    </visual>
    <visual>
      <geometry>
        <mesh filename="file:///home/jerry/tobesim/catkin_ws/src/tobe_description/assets/cad/FP04-F3_FCD-Conv_BDR-Col.dae" scale="0.001 0.001 0.001"/>
      </geometry>
      <origin rpy="0 3.141592653589793 0" xyz="0 -0.042 0"/>
    </visual>
    <visual>
      <geometry>
        <mesh filename="file:///home/jerry/tobesim/catkin_ws/src/tobe_description/assets/cad/FP04-F2_FCD-Conv_BDR-Col.dae" scale="0.001 0.001 0.001"/>
      </geometry>
      <origin rpy="-1.5707963267948966 0 0" xyz="0 -0.068 0"/>
    </visual>
    <collision name="r_hip_lateral_collision">
      <origin xyz="0 -0.0135 -0.0153"/>
      <geometry>
        <box size="0.04 0.051 0.0721"/>
      </geometry>
    </collision>
    <inertial>
      <mass value="0.3822870734"/>
      <origin xyz="-0.0000002032 -0.0068291604 -0.0006710552"/>
      <inertia ixx="0.0274690892" ixy="0.0000004066" ixz="-0.0000000859" iyy="0.0077817002" iyz="0.0007139012" izz="0.0226034759"/>
    </inertial>
  </link>
  <joint name="l_hip_lateral_joint" type="revolute">
    <parent link="l_hip_twist_link"/>
    <origin rpy="1.5707963267948966 0 0" xyz="0 0 0.047"/>
    <axis xyz="0 0 1"/>
    <child link="l_hip_lateral_link"/>
    <limit effort="10" lower="-0.8" upper="0.8" velocity="5.6548668"/>
  </joint>
  <link name="l_hip_lateral_link">
    <!-- Motor 10[l] -->
    <visual>
      <geometry>
        <mesh filename="file:///home/jerry/tobesim/catkin_ws/src/tobe_description/assets/cad/AX-12_FCD-Conv_BDR-Col.dae" scale="0.001 0.001 0.001"/>
      </geometry>
      <origin rpy="0 3.141592653589793 3.141592653589793" xyz="0 0 0"/>
    </visual>
    <visual>
      <geometry>
        <mesh filename="file:///home/jerry/tobesim/catkin_ws/src/tobe_description/assets/cad/FP04-F3_FCD-Conv_BDR-Col.dae" scale="0.001 0.001 0.001"/>
      </geometry>
      <origin rpy="0 0 3.141592653589793" xyz="0 0.042 0"/>
    </visual>
    <visual>
      <geometry>
        <mesh filename="file:///home/jerry/tobesim/catkin_ws/src/tobe_description/assets/cad/FP04-F2_FCD-Conv_BDR-Col.dae" scale="0.001 0.001 0.001"/>
      </geometry>
      <origin rpy="-1.5707963267948966 0 3.141592653589793" xyz="0 0.068 0"/>
    </visual>
    <collision name="l_hip_lateral_collision">
      <origin xyz="0 -0.0135 -0.0153"/>
      <geometry>
        <box size="0.04 0.051 0.0721"/>
      </geometry>
    </collision>
    <inertial>
      <mass value="0.3822870734"/>
      <origin xyz="0.0000002032 0.0068291604 -0.0006710552"/>
      <inertia ixx="0.0274690892" ixy="0.0000004066" ixz="0.0000000859" iyy="0.0077817002" iyz="-0.0007139012" izz="0.0226034759"/>
    </inertial>
  </link>
  <joint name="r_hip_swing_joint" type="revolute">
    <parent link="r_hip_lateral_link"/>
    <origin rpy="1.5707963267948966 0 -1.5707963267948966" xyz="0 -0.068 0"/>
    <axis xyz="0 0 1"/>
    <child link="r_upper_leg_link"/>
    <limit effort="30" lower="-2" upper="2" velocity="5.6548668"/>
    <!--<limit lower="${-0.8*(reflect-1)-2}" upper="${-0.8*(reflect+1)+2}" effort="10" velocity="5.6548668"/> -->
  </joint>
  <link name="r_upper_leg_link">
    <!-- Motor 11[r] -->
    <visual>
      <geometry>
        <mesh filename="file:///home/jerry/tobesim/catkin_ws/src/tobe_description/assets/cad/AX-12_FCD-Conv_BDR-Col.dae" scale="0.001 0.001 0.001"/>
      </geometry>
      <origin rpy="0 0 1.5707963267948966" xyz="0 0 0"/>
    </visual>
    <visual>
      <geometry>
        <mesh filename="file:///home/jerry/tobesim/catkin_ws/src/tobe_description/assets/cad/FP04-F3_FCD-Conv_BDR-Col.dae" scale="0.001 0.001 0.001"/>
      </geometry>
      <origin rpy="0 0 1.5707963267948966" xyz="0.042 0 0"/>
    </visual>
    <visual>
      <geometry>
        <mesh filename="file:///home/jerry/tobesim/catkin_ws/src/tobe_description/assets/cad/FP04-F1_FCD-Conv_BDR-Col.dae" scale="0.001 0.001 0.001"/>
      </geometry>
      <origin rpy="3.141592653589793 1.5707963267948966 0" xyz="0.065 0.0145 0"/>
    </visual>
    <collision name="r_upper_leg_proximal_collision">
      <origin xyz="0.0214 0 0"/>
      <geometry>
        <box size="0.065 0.03 0.049"/>
      </geometry>
    </collision>
    <collision name="r_upper_leg_distal_collision">
      <origin xyz="0.0675 0.0065 0"/>
      <geometry>
        <box size="0.04 0.0371 0.049"/>
      </geometry>
    </collision>
    <inertial>
      <mass value="0.1557654222"/>
      <origin xyz="-0.0012110096 0.0000000568 -0.0444074895"/>
      <inertia ixx="0.0867975538" ixy="-0.0000000255" ixz="0.0030686267" iyy="0.0784005596" iyz="-0.0000000875" izz="0.0138679533"/>
    </inertial>
  </link>
  <joint name="l_hip_swing_joint" type="revolute">
    <parent link="l_hip_lateral_link"/>
    <origin rpy="1.5707963267948966 0 -1.5707963267948966" xyz="0 0.068 0"/>
    <axis xyz="0 0 1"/>
    <child link="l_upper_leg_link"/>
    <limit effort="30" lower="-2" upper="2" velocity="5.6548668"/>
    <!--<limit lower="${-0.8*(reflect-1)-2}" upper="${-0.8*(reflect+1)+2}" effort="10" velocity="5.6548668"/> -->
  </joint>
  <link name="l_upper_leg_link">
    <!-- Motor 12[l] -->
    <visual>
      <geometry>
        <mesh filename="file:///home/jerry/tobesim/catkin_ws/src/tobe_description/assets/cad/AX-12_FCD-Conv_BDR-Col.dae" scale="0.001 0.001 0.001"/>
      </geometry>
      <origin rpy="0 0 -1.5707963267948966" xyz="0 0 0"/>
    </visual>
    <visual>
      <geometry>
        <mesh filename="file:///home/jerry/tobesim/catkin_ws/src/tobe_description/assets/cad/FP04-F3_FCD-Conv_BDR-Col.dae" scale="0.001 0.001 0.001"/>
      </geometry>
      <origin rpy="0 0 -1.5707963267948966" xyz="-0.042 0 0"/>
    </visual>
    <visual>
      <geometry>
        <mesh filename="file:///home/jerry/tobesim/catkin_ws/src/tobe_description/assets/cad/FP04-F1_FCD-Conv_BDR-Col.dae" scale="0.001 0.001 0.001"/>
      </geometry>
      <origin rpy="3.141592653589793 -1.5707963267948966 0" xyz="-0.065 0.0145 0"/>
    </visual>
    <collision name="l_upper_leg_proximal_collision">
      <origin xyz="0.0214 0 0"/>
      <geometry>
        <box size="0.065 0.03 0.049"/>
      </geometry>
    </collision>
    <collision name="l_upper_leg_distal_collision">
      <origin xyz="0.0675 0.0065 0"/>
      <geometry>
        <box size="0.04 0.0371 0.049"/>
      </geometry>
    </collision>
    <inertial>
      <mass value="0.1557654222"/>
      <origin xyz="-0.0012110096 0.0000000568 -0.0444074895"/>
      <inertia ixx="0.0867975538" ixy="-0.0000000255" ixz="0.0030686267" iyy="0.0784005596" iyz="-0.0000000875" izz="0.0138679533"/>
    </inertial>
  </link>
  <!-- KNEES -->
  <joint name="r_knee_joint" type="revolute">
    <parent link="r_upper_leg_link"/>
    <origin rpy="0 0 0" xyz="0.065 0.0145 0"/>
    <axis xyz="0 0 1"/>
    <child link="r_lower_leg_link"/>
    <limit effort="10" lower="0" upper="2" velocity="5.6548668"/>
  </joint>
  <link name="r_lower_leg_link">
    <!-- Motor 13[r] -->
    <visual>
      <geometry>
        <mesh filename="file:///home/jerry/tobesim/catkin_ws/src/tobe_description/assets/cad/AX-12_FCD-Conv_BDR-Col.dae" scale="0.001 0.001 0.001"/>
      </geometry>
      <origin rpy="0 0 0" xyz="0 0 0"/>
    </visual>
    <visual>
      <geometry>
        <mesh filename="file:///home/jerry/tobesim/catkin_ws/src/tobe_description/assets/cad/FP04-F3_FCD-Conv_BDR-Col.dae" scale="0.001 0.001 0.001"/>
      </geometry>
      <origin rpy="0 0 1.5707963267948966" xyz="0.02 -0.0145 0"/>
    </visual>
    <visual>
      <geometry>
        <mesh filename="file:///home/jerry/tobesim/catkin_ws/src/tobe_description/assets/cad/FP04-F3_FCD-Conv_BDR-Col.dae" scale="0.001 0.001 0.001"/>
      </geometry>
      <origin rpy="0 0 -1.5707963267948966" xyz="0.02 -0.0145 0"/>
    </visual>
    <visual>
      <geometry>
        <mesh filename="file:///home/jerry/tobesim/catkin_ws/src/tobe_description/assets/cad/AX-12_FCD-Conv_BDR-Col.dae" scale="0.001 0.001 0.001"/>
      </geometry>
      <origin rpy=" 0 3.141592653589793 -1.5707963267948966" xyz="0.062 -0.0145 0"/>
    </visual>
    <collision name="r_lower_leg_proximal_collision">
      <origin xyz="0 -0.0135 0"/>
      <geometry>
        <box size="0.033 0.051 0.044"/>
      </geometry>
    </collision>
    <collision name="r_lower_leg_distal_collision">
      <origin xyz="0.0492 -0.0145 0"/>
      <geometry>
        <box size="0.067 0.03 0.049"/>
      </geometry>
    </collision>
    <inertial>
      <mass value="0.4326089335"/>
      <origin xyz="-0.0010052500 -0.0012675002 -0.0110864377"/>
      <inertia ixx="0.0542924849" ixy="0.0002115982" ixz="0.0010887655" iyy="0.0479327441" iyz="0.0019185952" izz="0.0137425373"/>
    </inertial>
  </link>
  <joint name="l_knee_joint" type="revolute">
    <parent link="l_upper_leg_link"/>
    <origin rpy="0 0 0" xyz="-0.065 0.0145 0"/>
    <axis xyz="0 0 1"/>
    <child link="l_lower_leg_link"/>
    <limit effort="10" lower="-2" upper="0" velocity="5.6548668"/>
  </joint>
  <link name="l_lower_leg_link">
    <!-- Motor 14[l] -->
    <visual>
      <geometry>
        <mesh filename="file:///home/jerry/tobesim/catkin_ws/src/tobe_description/assets/cad/AX-12_FCD-Conv_BDR-Col.dae" scale="0.001 0.001 0.001"/>
      </geometry>
      <origin rpy="0 0 0" xyz="0 0 0"/>
    </visual>
    <visual>
      <geometry>
        <mesh filename="file:///home/jerry/tobesim/catkin_ws/src/tobe_description/assets/cad/FP04-F3_FCD-Conv_BDR-Col.dae" scale="0.001 0.001 0.001"/>
      </geometry>
      <origin rpy="0 0 -1.5707963267948966" xyz="-0.02 -0.0145 0"/>
    </visual>
    <visual>
      <geometry>
        <mesh filename="file:///home/jerry/tobesim/catkin_ws/src/tobe_description/assets/cad/FP04-F3_FCD-Conv_BDR-Col.dae" scale="0.001 0.001 0.001"/>
      </geometry>
      <origin rpy="0 0 1.5707963267948966" xyz="-0.02 -0.0145 0"/>
    </visual>
    <visual>
      <geometry>
        <mesh filename="file:///home/jerry/tobesim/catkin_ws/src/tobe_description/assets/cad/AX-12_FCD-Conv_BDR-Col.dae" scale="0.001 0.001 0.001"/>
      </geometry>
      <origin rpy=" 0 3.141592653589793 1.5707963267948966" xyz="-0.062 -0.0145 0"/>
    </visual>
    <collision name="l_lower_leg_proximal_collision">
      <origin xyz="0 -0.0135 0"/>
      <geometry>
        <box size="0.033 0.051 0.044"/>
      </geometry>
    </collision>
    <collision name="l_lower_leg_distal_collision">
      <origin xyz="0.0492 -0.0145 0"/>
      <geometry>
        <box size="0.067 0.03 0.049"/>
      </geometry>
    </collision>
    <inertial>
      <mass value="0.4326089335"/>
      <origin xyz="-0.0010052500 0.0002674591 -0.0110862203"/>
      <inertia ixx="0.0541596500" ixy="-0.0001245680" ixz="0.0010887872" iyy="0.0479327482" iyz="-0.0009590411" izz="0.0136097320"/>
    </inertial>
  </link>
  <!-- ANKLES -->
  <joint name="r_ankle_swing_joint" type="revolute">
    <parent link="r_lower_leg_link"/>
    <origin rpy="3.141592653589793 0 0" xyz="0.062 -0.0145 0"/>
    <axis xyz="0 0 1"/>
    <child link="r_ankle_swing_link"/>
    <limit effort="10" lower="-0.3999999999999999" upper="2.0" velocity="5.6548668"/>
  </joint>
  <link name="r_ankle_swing_link">
    <!-- Motor 15[r]  -->
    <visual>
      <geometry>
        <mesh filename="file:///home/jerry/tobesim/catkin_ws/src/tobe_description/assets/cad/FP04-F2_FCD-Conv_BDR-Col.dae" scale="0.001 0.001 0.001"/>
      </geometry>
      <origin rpy="0 1.5707963267948966 0" xyz="-0.0005 0 0"/>
    </visual>
    <visual>
      <geometry>
        <mesh filename="file:///home/jerry/tobesim/catkin_ws/src/tobe_description/assets/cad/FP04-F3_FCD-Conv_BDR-Col.dae" scale="0.001 0.001 0.001"/>
      </geometry>
      <origin rpy="0 -1.5707963267948966 -1.5707963267948966" xyz="0.0255 0 0"/>
    </visual>
    <collision name="r_ankle_swing_collision">
      <origin xyz="-0.0135 -0.0167 0"/>
      <geometry>
        <box size="0.051 0.0721 0.04"/>
      </geometry>
    </collision>
    <inertial>
      <mass value="0.3822870734"/>
      <origin xyz="-0.0000002032 -0.0068291604 -0.0006710552"/>
      <inertia ixx="0.0274690892" ixy="0.0000004066" ixz="-0.0000000859" iyy="0.0077817002" iyz="0.0007139012" izz="0.0226034759"/>
    </inertial>
  </link>
  <joint name="l_ankle_swing_joint" type="revolute">
    <parent link="l_lower_leg_link"/>
    <origin rpy="3.141592653589793 0 0" xyz="-0.062 -0.0145 0"/>
    <axis xyz="0 0 1"/>
    <child link="l_ankle_swing_link"/>
    <limit effort="10" lower="-2.0" upper="0.3999999999999999" velocity="5.6548668"/>
  </joint>
  <link name="l_ankle_swing_link">
    <!-- Motor 16[l] -->
    <visual>
      <geometry>
        <mesh filename="file:///home/jerry/tobesim/catkin_ws/src/tobe_description/assets/cad/FP04-F2_FCD-Conv_BDR-Col.dae" scale="0.001 0.001 0.001"/>
      </geometry>
      <origin rpy="0 -1.5707963267948966 0" xyz="0.0005 0 0"/>
    </visual>
    <visual>
      <geometry>
        <mesh filename="file:///home/jerry/tobesim/catkin_ws/src/tobe_description/assets/cad/FP04-F3_FCD-Conv_BDR-Col.dae" scale="0.001 0.001 0.001"/>
      </geometry>
      <origin rpy="0 1.5707963267948966 1.5707963267948966" xyz="-0.0255 0 0"/>
    </visual>
    <collision name="l_ankle_swing_collision">
      <origin xyz="-0.0135 -0.0167 0"/>
      <geometry>
        <box size="0.051 0.0721 0.04"/>
      </geometry>
    </collision>
    <inertial>
      <mass value="0.3822870734"/>
      <origin xyz="0.0000002032 0.0068291604 -0.0006710552"/>
      <inertia ixx="0.0274690892" ixy="0.0000004066" ixz="0.0000000859" iyy="0.0077817002" iyz="-0.0007139012" izz="0.0226034759"/>
    </inertial>
  </link>
  <joint name="r_ankle_lateral_joint" type="revolute">
    <parent link="r_ankle_swing_link"/>
    <origin rpy="-1.5707963267948966 0 0" xyz="0.045 0 -0.012"/>
    <axis xyz="0 0 1"/>
    <child link="r_ankle_lateral_link"/>
    <limit effort="10" lower="-0.8" upper="0.8" velocity="5.6548668"/>
  </joint>
  <link name="r_ankle_lateral_link">
    <!-- Motor 17[r] -->
    <visual>
      <geometry>
        <mesh filename="file:///home/jerry/tobesim/catkin_ws/src/tobe_description/assets/cad/AX-12_FCD-Conv_BDR-Col.dae" scale="0.001 0.001 0.001"/>
      </geometry>
      <origin rpy="0 0 0" xyz="0 0 0"/>
    </visual>
    <visual>
      <geometry>
        <mesh filename="file:///home/jerry/tobesim/catkin_ws/src/tobe_description/assets/cad/FP04-F2_FCD-Conv_BDR-Col.dae" scale="0.001 0.001 0.001"/>
      </geometry>
      <origin rpy="0 1.5707963267948966 0" xyz="0 0 0"/>
    </visual>
    <collision name="r_ankle_lateral_collision">
      <origin xyz="0.009 0 -0.016"/>
      <geometry>
        <box size="0.0405 0.029 0.083"/>
      </geometry>
    </collision>
  </link>
  <joint name="l_ankle_lateral_joint" type="revolute">
    <parent link="l_ankle_swing_link"/>
    <origin rpy="-1.5707963267948966 0 0" xyz="-0.045 0 -0.012"/>
    <axis xyz="0 0 1"/>
    <child link="l_ankle_lateral_link"/>
    <limit effort="10" lower="-0.8" upper="0.8" velocity="5.6548668"/>
  </joint>
  <link name="l_ankle_lateral_link">
    <!-- Motor 18[l] -->
    <visual>
      <geometry>
        <mesh filename="file:///home/jerry/tobesim/catkin_ws/src/tobe_description/assets/cad/AX-12_FCD-Conv_BDR-Col.dae" scale="0.001 0.001 0.001"/>
      </geometry>
      <origin rpy="0 0 0" xyz="0 0 0"/>
    </visual>
    <visual>
      <geometry>
        <mesh filename="file:///home/jerry/tobesim/catkin_ws/src/tobe_description/assets/cad/FP04-F2_FCD-Conv_BDR-Col.dae" scale="0.001 0.001 0.001"/>
      </geometry>
      <origin rpy="0 -1.5707963267948966 0" xyz="0 0 0"/>
    </visual>
    <collision name="l_ankle_lateral_collision">
      <origin xyz="0.009 0 -0.016"/>
      <geometry>
        <box size="0.0405 0.029 0.083"/>
      </geometry>
    </collision>
  </link>
  <!-- UPPER BODY -->
  <!-- Base -->
  <joint name="base_to_torso_joint" type="fixed">
    <parent link="base_link"/>
    <origin rpy="0 0 0" xyz="0 0 0"/>
    <child link="torso_link"/>
  </joint>
  <link name="base_link">
    </link>
  <joint name="r_shoulder_swing_joint" type="revolute">
    <parent link="torso_link"/>
    <origin rpy="1.5707963267948966 3.141592653589793 0" xyz="0 -0.032 0"/>
    <axis xyz="0 0 1"/>
    <child link="r_shoulder_swing_link"/>
    <limit effort="2.8" lower="-1" upper="1.5707963267948966" velocity="1.0"/>
  </joint>
  <link name="r_shoulder_swing_link">
    <visual>
      <geometry>
        <mesh filename="file:///home/jerry/tobesim/catkin_ws/src/tobe_description/assets/cad/FP04-F1_FCD-Conv_BDR-Col.dae" scale="0.001 0.001 0.001"/>
      </geometry>
      <origin rpy="0 3.141592653589793 3.141592653589793" xyz="0 0.014 0.044"/>
    </visual>
    <collision name="r_shoulder_collision">
      <origin xyz="0 0.006 0.0375"/>
      <geometry>
        <box size="0.052 0.039 0.036"/>
      </geometry>
    </collision>
    <inertial>
      <mass value="0.0595945816"/>
      <origin xyz="-0.0109359544 0.0123630374 -0.0000000007"/>
      <inertia ixx="0.0069903407" ixy="-0.0020812370" ixz="0.0000000001" iyy="0.0067210939" iyz="-0.0000000002" izz="0.0054521983"/>
    </inertial>
  </link>
  <joint name="l_shoulder_swing_joint" type="revolute">
    <parent link="torso_link"/>
    <origin rpy="-1.5707963267948966 0.0 0" xyz="0 0.032 0"/>
    <axis xyz="0 0 1"/>
    <child link="l_shoulder_swing_link"/>
    <limit effort="2.8" lower="-1" upper="1.5707963267948966" velocity="1.0"/>
  </joint>
  <link name="l_shoulder_swing_link">
    <visual>
      <geometry>
        <mesh filename="file:///home/jerry/tobesim/catkin_ws/src/tobe_description/assets/cad/FP04-F1_FCD-Conv_BDR-Col.dae" scale="0.001 0.001 0.001"/>
      </geometry>
      <origin rpy="0 3.141592653589793 3.141592653589793" xyz="0 0.014 0.044"/>
    </visual>
    <collision name="l_shoulder_collision">
      <origin xyz="0 0.006 0.0375"/>
      <geometry>
        <box size="0.052 0.039 0.036"/>
      </geometry>
    </collision>
    <inertial>
      <mass value="0.0595945816"/>
      <origin xyz="-0.0109359544 -0.0123630374 0.0000000007"/>
      <inertia ixx="0.0069903407" ixy="0.0020812370" ixz="-0.0000000001" iyy="0.0067210939" iyz="-0.0000000002" izz="0.0054521983"/>
    </inertial>
  </link>
  <joint name="r_shoulder_lateral_joint" type="revolute">
    <parent link="r_shoulder_swing_link"/>
    <origin rpy="0 -1.5707963267948966 0" xyz="0 0.014 0.044"/>
    <axis xyz="0 0 1"/>
    <child link="r_upper_arm_link"/>
    <limit effort="2.8" lower="-1.5" upper="1.5" velocity="1.0"/>
  </joint>
  <link name="r_upper_arm_link">
    <visual>
      <geometry>
        <mesh filename="file:///home/jerry/tobesim/catkin_ws/src/tobe_description/assets/cad/AX-12_FCD-Conv_BDR-Col.dae" scale="0.001 0.001 0.001"/>
      </geometry>
      <origin rpy="0 0 3.141592653589793" xyz="0 0 0"/>
    </visual>
    <visual>
      <geometry>
        <mesh filename="file:///home/jerry/tobesim/catkin_ws/src/tobe_description/assets/cad/FP04-F3_FCD-Conv_BDR-Col.dae" scale="0.001 0.001 0.001"/>
      </geometry>
      <origin rpy="0 0 3.141592653589793" xyz="0 0.0415 0"/>
    </visual>
    <visual>
      <geometry>
        <mesh filename="file:///home/jerry/tobesim/catkin_ws/src/tobe_description/assets/cad/FP04-F2_FCD-Conv_BDR-Col.dae" scale="0.001 0.001 0.001"/>
      </geometry>
      <origin rpy="1.5707963267948966 0 0" xyz="0 0.0675 0"/>
    </visual>
    <collision name="r_upper arm_collision_proximal">
      <origin xyz="0.0148 0 0"/>
      <geometry>
        <box size="0.054 0.033 0.044"/>
      </geometry>
    </collision>
    <collision name="r_upper arm_collision_distal">
      <origin xyz="0.0555 0 0"/>
      <geometry>
        <box size="0.047 0.033 0.052"/>
      </geometry>
    </collision>
    <inertial>
      <mass value="0.3822870734"/>
      <origin xyz="-0.0000002032 -0.0068291604 -0.0006710552"/>
      <inertia ixx="0.0274690892" ixy="0.0000004066" ixz="-0.0000000859" iyy="0.0077817002" iyz="0.0007139012" izz="0.0226034759"/>
    </inertial>
  </link>
  <joint name="l_shoulder_lateral_joint" type="revolute">
    <parent link="l_shoulder_swing_link"/>
    <origin rpy="0 -1.5707963267948966 0" xyz="0 0.014 0.044"/>
    <axis xyz="0 0 1"/>
    <child link="l_upper_arm_link"/>
    <limit effort="2.8" lower="-1.5" upper="1.5" velocity="1.0"/>
  </joint>
  <link name="l_upper_arm_link">
    <visual>
      <geometry>
        <mesh filename="file:///home/jerry/tobesim/catkin_ws/src/tobe_description/assets/cad/AX-12_FCD-Conv_BDR-Col.dae" scale="0.001 0.001 0.001"/>
      </geometry>
      <origin rpy="0 3.141592653589793 3.141592653589793" xyz="0 0 0"/>
    </visual>
    <visual>
      <geometry>
        <mesh filename="file:///home/jerry/tobesim/catkin_ws/src/tobe_description/assets/cad/FP04-F3_FCD-Conv_BDR-Col.dae" scale="0.001 0.001 0.001"/>
      </geometry>
      <origin rpy="0 0 3.141592653589793" xyz="0 0.0415 0"/>
    </visual>
    <visual>
      <geometry>
        <mesh filename="file:///home/jerry/tobesim/catkin_ws/src/tobe_description/assets/cad/FP04-F2_FCD-Conv_BDR-Col.dae" scale="0.001 0.001 0.001"/>
      </geometry>
      <origin rpy="1.5707963267948966 0 0" xyz="0 0.0675 0"/>
    </visual>
    <collision name="l_upper arm_collision_proximal">
      <origin xyz="0.0148 0 0"/>
      <geometry>
        <box size="0.054 0.033 0.044"/>
      </geometry>
    </collision>
    <collision name="l_upper arm_collision_distal">
      <origin xyz="0.0555 0 0"/>
      <geometry>
        <box size="0.047 0.033 0.052"/>
      </geometry>
    </collision>
    <inertial>
      <mass value="0.3822870734"/>
      <origin xyz="0.0000002032 0.0068291604 -0.0006710552"/>
      <inertia ixx="0.0274690892" ixy="0.0000004066" ixz="0.0000000859" iyy="0.0077817002" iyz="-0.0007139012" izz="0.0226034759"/>
    </inertial>
  </link>
  <joint name="r_elbow_joint" type="revolute">
    <parent link="r_upper_arm_link"/>
    <origin rpy="0 -1.5707963267948966 3.141592653589793" xyz="0 0.0675 0"/>
    <axis xyz="0 0 1"/>
    <axis xyz="0 0 1"/>
    <child link="r_lower_arm_link"/>
    <limit effort="2.8" lower="-1.77" upper="1.77" velocity="1.0"/>
  </joint>
  <link name="r_lower_arm_link">
    <!-- Motor 5 -->
    <visual>
      <geometry>
        <mesh filename="file:///home/jerry/tobesim/catkin_ws/src/tobe_description/assets/cad/AX-12_FCD-Conv_BDR-Col.dae" scale="0.001 0.001 0.001"/>
      </geometry>
      <origin rpy="0 0 0" xyz="0 0 0"/>
    </visual>
    <visual>
      <geometry>
        <mesh filename="file:///home/jerry/tobesim/catkin_ws/src/tobe_description/assets/cad/FP04-F3_FCD-Conv_BDR-Col.dae" scale="0.001 0.001 0.001"/>
      </geometry>
      <origin rpy="0 0 0" xyz="0 -0.0415 0"/>
    </visual>
    <collision name="r_lower_arm_collision">
      <origin xyz="0 0.017 0"/>
      <geometry>
        <box size="0.058 0.033 0.044"/>
      </geometry>
    </collision>
    <inertial>
      <mass value="0.3833833954"/>
      <origin xyz="-0.0009848283 -0.0081892817 -0.0005847510"/>
      <inertia ixx="0.0336009689" ixy="0.0038318932" ixz="0.0000784112" iyy="0.0055167096" iyz="0.0008760966" izz="0.0319185839"/>
    </inertial>
  </link>
  <joint name="l_elbow_joint" type="revolute">
    <parent link="l_upper_arm_link"/>
    <origin rpy="0 -1.5707963267948966 3.141592653589793" xyz="0 0.0675 0"/>
    <axis xyz="0 0 1"/>
    <axis xyz="0 0 1"/>
    <child link="l_lower_arm_link"/>
    <limit effort="2.8" lower="-1.77" upper="1.77" velocity="1.0"/>
  </joint>
  <link name="l_lower_arm_link">
    <!-- Motor 6 -->
    <visual>
      <geometry>
        <mesh filename="file:///home/jerry/tobesim/catkin_ws/src/tobe_description/assets/cad/AX-12_FCD-Conv_BDR-Col.dae" scale="0.001 0.001 0.001"/>
      </geometry>
      <origin rpy="0 0 0" xyz="0 0 0"/>
    </visual>
    <visual>
      <geometry>
        <mesh filename="file:///home/jerry/tobesim/catkin_ws/src/tobe_description/assets/cad/FP04-F3_FCD-Conv_BDR-Col.dae" scale="0.001 0.001 0.001"/>
      </geometry>
      <origin rpy="0 0 0" xyz="0 -0.0415 0"/>
    </visual>
    <collision name="l_lower_arm_collision">
      <origin xyz="0 0.017 0"/>
      <geometry>
        <box size="0.058 0.033 0.044"/>
      </geometry>
    </collision>
    <inertial>
      <mass value="0.3822870734"/>
      <origin xyz="0.0000002032 0.0068291604 -0.0006710552"/>
      <inertia ixx="0.0274690892" ixy="0.0000004066" ixz="0.0000000859" iyy="0.0077817002" iyz="-0.0007139012" izz="0.0226034759"/>
    </inertial>
  </link>
  <joint name="r_hand_joint" type="fixed">
    <parent link="r_lower_arm_link"/>
    <origin rpy="0 0 0" xyz="0 0 0"/>
    <child link="r_hand_link"/>
  </joint>
  <link name="r_hand_link">
    <visual>
      <geometry>
        <mesh filename="file:///home/jerry/tobesim/catkin_ws/src/tobe_description/assets/cad/FP04-F11_FCD-Conv_BDR-Col.dae" scale="0.001 0.001 0.001"/>
      </geometry>
      <origin rpy="1.5707963267948966 0 0" xyz="0 -0.0415 0"/>
    </visual>
    <collision name="r_palm_collision">
      <origin xyz="0.039 0 0"/>
      <geometry>
        <box size="0.0131 0.0265 0.044"/>
      </geometry>
    </collision>
    <collision name="r_fingers_collision">
      <origin xyz="0.0701 -0.0077 0"/>
      <geometry>
        <box size="0.0575 0.0175 0.035"/>
      </geometry>
    </collision>
    <inertial>
      <mass value="0.0303003163"/>
      <origin xyz="-0.0070414665 -0.0217364083 -0.0000000095"/>
      <inertia ixx="0.0054448143" ixy="0.0011266691" ixz="0.0000000017" iyy="0.0013220979" iyz="-0.0000000025" izz="0.0053756998"/>
    </inertial>
  </link>
  <joint name="l_hand_joint" type="fixed">
    <parent link="l_lower_arm_link"/>
    <origin rpy="0 0 0" xyz="0 0 0"/>
    <child link="l_hand_link"/>
  </joint>
  <link name="l_hand_link">
    <visual>
      <geometry>
        <mesh filename="file:///home/jerry/tobesim/catkin_ws/src/tobe_description/assets/cad/FP04-F11_FCD-Conv_BDR-Col.dae" scale="0.001 0.001 0.001"/>
      </geometry>
      <origin rpy="1.5707963267948966 0 0" xyz="0 -0.0415 0"/>
    </visual>
    <collision name="l_palm_collision">
      <origin xyz="0.039 0 0"/>
      <geometry>
        <box size="0.0131 0.0265 0.044"/>
      </geometry>
    </collision>
    <collision name="l_fingers_collision">
      <origin xyz="0.0701 -0.0077 0"/>
      <geometry>
        <box size="0.0575 0.0175 0.035"/>
      </geometry>
    </collision>
    <inertial>
      <mass value="0.0303003163"/>
      <origin xyz="-0.0070414665 0.0217364083 0.0000000095"/>
      <inertia ixx="0.0054448143" ixy="-0.0011266691" ixz="-0.0000000017" iyy="0.0013220979" iyz="-0.0000000025" izz="0.0053756998"/>
    </inertial>
  </link>
  <joint name="r_foot_joint" type="fixed">
    <parent link="r_ankle_lateral_link"/>
    <origin rpy="0 0 0" xyz="0 -0.004 0.01"/>
    <child link="r_foot_link"/>
  </joint>
  <gazebo reference="r_foot_link">
    <mu1>10</mu1>
    <!-- 9000 -->
    <mu2>10</mu2>
    <!-- 9000 -->
    <kp>1000000.0</kp>
    <kd>10.0</kd>
    <minDepth>0.001</minDepth>
    <maxContacts>1</maxContacts>
  </gazebo>
  <joint name="l_foot_joint" type="fixed">
    <parent link="l_ankle_lateral_link"/>
    <origin rpy="0 0 0" xyz="0 -0.004 0.01"/>
    <child link="l_foot_link"/>
  </joint>
  <gazebo reference="l_foot_link">
    <mu1>10</mu1>
    <!-- 9000 -->
    <mu2>10</mu2>
    <!-- 9000 -->
    <kp>1000000.0</kp>
    <kd>10.0</kd>
    <minDepth>0.001</minDepth>
    <maxContacts>1</maxContacts>
  </gazebo>
  <transmission name="r_shoulder_swing_joint_tran">
    <type>transmission_interface/SimpleTransmission</type>
    <joint name="r_shoulder_swing_joint">
      <hardwareInterface>hardware_interface/EffortJointInterface</hardwareInterface>
    </joint>
    <actuator name="r_shoulder_swing_joint_motor">
      <hardwareInterface>hardware_interface/EffortJointInterface</hardwareInterface>
      <mechanicalReduction>1</mechanicalReduction>
    </actuator>
  </transmission>
  <transmission name="l_shoulder_swing_joint_tran">
    <type>transmission_interface/SimpleTransmission</type>
    <joint name="l_shoulder_swing_joint">
      <hardwareInterface>hardware_interface/EffortJointInterface</hardwareInterface>
    </joint>
    <actuator name="l_shoulder_swing_joint_motor">
      <hardwareInterface>hardware_interface/EffortJointInterface</hardwareInterface>
      <mechanicalReduction>1</mechanicalReduction>
    </actuator>
  </transmission>
  <transmission name="r_shoulder_lateral_joint_tran">
    <type>transmission_interface/SimpleTransmission</type>
    <joint name="r_shoulder_lateral_joint">
      <hardwareInterface>hardware_interface/EffortJointInterface</hardwareInterface>
    </joint>
    <actuator name="r_shoulder_lateral_joint_motor">
      <hardwareInterface>hardware_interface/EffortJointInterface</hardwareInterface>
      <mechanicalReduction>1</mechanicalReduction>
    </actuator>
  </transmission>
  <transmission name="l_shoulder_lateral_joint_tran">
    <type>transmission_interface/SimpleTransmission</type>
    <joint name="l_shoulder_lateral_joint">
      <hardwareInterface>hardware_interface/EffortJointInterface</hardwareInterface>
    </joint>
    <actuator name="l_shoulder_lateral_joint_motor">
      <hardwareInterface>hardware_interface/EffortJointInterface</hardwareInterface>
      <mechanicalReduction>1</mechanicalReduction>
    </actuator>
  </transmission>
  <transmission name="r_elbow_joint_tran">
    <type>transmission_interface/SimpleTransmission</type>
    <joint name="r_elbow_joint">
      <hardwareInterface>hardware_interface/EffortJointInterface</hardwareInterface>
    </joint>
    <actuator name="r_elbow_joint_motor">
      <hardwareInterface>EffortJointInterface</hardwareInterface>
      <mechanicalReduction>1</mechanicalReduction>
    </actuator>
  </transmission>
  <transmission name="l_elbow_joint_tran">
    <type>transmission_interface/SimpleTransmission</type>
    <joint name="l_elbow_joint">
      <hardwareInterface>hardware_interface/EffortJointInterface</hardwareInterface>
    </joint>
    <actuator name="l_elbow_joint_motor">
      <hardwareInterface>EffortJointInterface</hardwareInterface>
      <mechanicalReduction>1</mechanicalReduction>
    </actuator>
  </transmission>
  <transmission name="r_hip_twist_joint_tran">
    <type>transmission_interface/SimpleTransmission</type>
    <joint name="r_hip_twist_joint">
      <hardwareInterface>hardware_interface/EffortJointInterface</hardwareInterface>
    </joint>
    <actuator name="r_hip_twist_joint_motor">
      <hardwareInterface>hardware_interface/EffortJointInterface</hardwareInterface>
      <mechanicalReduction>1</mechanicalReduction>
    </actuator>
  </transmission>
  <transmission name="l_hip_twist_joint_tran">
    <type>transmission_interface/SimpleTransmission</type>
    <joint name="l_hip_twist_joint">
      <hardwareInterface>hardware_interface/EffortJointInterface</hardwareInterface>
    </joint>
    <actuator name="l_hip_twist_joint_motor">
      <hardwareInterface>hardware_interface/EffortJointInterface</hardwareInterface>
      <mechanicalReduction>1</mechanicalReduction>
    </actuator>
  </transmission>
  <transmission name="r_hip_lateral_joint_tran">
    <type>transmission_interface/SimpleTransmission</type>
    <joint name="r_hip_lateral_joint">
      <hardwareInterface>hardware_interface/EffortJointInterface</hardwareInterface>
    </joint>
    <actuator name="r_hip_lateral_joint_motor">
      <hardwareInterface>hardware_interface/EffortJointInterface</hardwareInterface>
      <mechanicalReduction>1</mechanicalReduction>
    </actuator>
  </transmission>
  <transmission name="l_hip_lateral_joint_tran">
    <type>transmission_interface/SimpleTransmission</type>
    <joint name="l_hip_lateral_joint">
      <hardwareInterface>hardware_interface/EffortJointInterface</hardwareInterface>
    </joint>
    <actuator name="l_hip_lateral_joint_motor">
      <hardwareInterface>hardware_interface/EffortJointInterface</hardwareInterface>
      <mechanicalReduction>1</mechanicalReduction>
    </actuator>
  </transmission>
  <transmission name="r_hip_swing_joint_tran">
    <type>transmission_interface/SimpleTransmission</type>
    <joint name="r_hip_swing_joint">
      <hardwareInterface>hardware_interface/EffortJointInterface</hardwareInterface>
    </joint>
    <actuator name="r_hip_swing_joint_motor">
      <hardwareInterface>hardware_interface/EffortJointInterface</hardwareInterface>
      <mechanicalReduction>1</mechanicalReduction>
    </actuator>
  </transmission>
  <transmission name="l_hip_swing_joint_tran">
    <type>transmission_interface/SimpleTransmission</type>
    <joint name="l_hip_swing_joint">
      <hardwareInterface>hardware_interface/EffortJointInterface</hardwareInterface>
    </joint>
    <actuator name="l_hip_swing_joint_motor">
      <hardwareInterface>hardware_interface/EffortJointInterface</hardwareInterface>
      <mechanicalReduction>1</mechanicalReduction>
    </actuator>
  </transmission>
  <transmission name="r_knee_joint_tran">
    <type>transmission_interface/SimpleTransmission</type>
    <joint name="r_knee_joint">
      <hardwareInterface>hardware_interface/EffortJointInterface</hardwareInterface>
    </joint>
    <actuator name="r_knee_joint_motor">
      <hardwareInterface>hardware_interface/EffortJointInterface</hardwareInterface>
      <mechanicalReduction>1</mechanicalReduction>
    </actuator>
  </transmission>
  <transmission name="l_knee_joint_tran">
    <type>transmission_interface/SimpleTransmission</type>
    <joint name="l_knee_joint">
      <hardwareInterface>hardware_interface/EffortJointInterface</hardwareInterface>
    </joint>
    <actuator name="l_knee_joint_motor">
      <hardwareInterface>hardware_interface/EffortJointInterface</hardwareInterface>
      <mechanicalReduction>1</mechanicalReduction>
    </actuator>
  </transmission>
  <transmission name="r_ankle_swing_joint_tran">
    <type>transmission_interface/SimpleTransmission</type>
    <joint name="r_ankle_swing_joint">
      <hardwareInterface>hardware_interface/EffortJointInterface</hardwareInterface>
    </joint>
    <actuator name="r_ankle_swing_joint_motor">
      <hardwareInterface>hardware_interface/EffortJointInterface</hardwareInterface>
      <mechanicalReduction>1</mechanicalReduction>
    </actuator>
  </transmission>
  <transmission name="l_ankle_swing_joint_tran">
    <type>transmission_interface/SimpleTransmission</type>
    <joint name="l_ankle_swing_joint">
      <hardwareInterface>hardware_interface/EffortJointInterface</hardwareInterface>
    </joint>
    <actuator name="l_ankle_swing_joint_motor">
      <hardwareInterface>hardware_interface/EffortJointInterface</hardwareInterface>
      <mechanicalReduction>1</mechanicalReduction>
    </actuator>
  </transmission>
  <transmission name="r_ankle_lateral_joint_tran">
    <type>transmission_interface/SimpleTransmission</type>
    <joint name="r_ankle_lateral_joint">
      <hardwareInterface>hardware_interface/EffortJointInterface</hardwareInterface>
    </joint>
    <actuator name="r_ankle_lateral_joint_motor">
      <hardwareInterface>hardware_interface/EffortJointInterface</hardwareInterface>
      <mechanicalReduction>1</mechanicalReduction>
    </actuator>
  </transmission>
  <transmission name="l_ankle_lateral_joint_tran">
    <type>transmission_interface/SimpleTransmission</type>
    <joint name="l_ankle_lateral_joint">
      <hardwareInterface>hardware_interface/EffortJointInterface</hardwareInterface>
    </joint>
    <actuator name="l_ankle_lateral_joint_motor">
      <hardwareInterface>hardware_interface/EffortJointInterface</hardwareInterface>
      <mechanicalReduction>1</mechanicalReduction>
    </actuator>
  </transmission>
</robot>

